Workbook

Sheet Auction
A1: 🏏 CRICKET AUCTION — MASTER LIST
A2: Every player is listed below. For each SOLD player type the Price (CRORES: 1.20 = 1cr 20L) and pick the buying Team from the drop-down. Role / Base / Grade are pre-filled. Filter by Grade, Role or Team.
A4: Player | B4: Price (Cr) | C4: Team | D4: Role | E4: Base (Cr) | F4: Grade | H4: Pool size | I4: =COUNTA(A5:A1000)
A5: Virat Kohli | B5: 27.5 | C5: Imphal Igniter | D5: =IFERROR(T(VLOOKUP($A5,Players!$A:$E,2,FALSE)),"") | E5: 3 | F5: A | H5: Players sold | I5: =COUNTA(C5:C1000)
A6: Sai Sudharsan | B6: 23.5 | C6: Gujarat Titans | D6: =IFERROR(T(VLOOKUP($A6,Players!$A:$E,2,FALSE)),"") | E6: 3 | F6: A | H6: Total spend (Cr) | I6: =SUM(B5:B1000)
A7: Suryakumar Yadav | B7: 21.5 | C7: Patna Panthers | D7: =IFERROR(T(VLOOKUP($A7,Players!$A:$E,2,FALSE)),"") | E7: 3 | F7: A
A8: Shubman Gill | B8: 28 | C8: Punjab Kings | D8: =IFERROR(T(VLOOKUP($A8,Players!$A:$E,2,FALSE)),"") | E8: 3 | F8: A
A9: Nicholas Pooran | D9: =IFERROR(T(VLOOKUP($A9,Players!$A:$E,2,FALSE)),"") | E9: 3 | F9: A
A10: Travis Head | D10: =IFERROR(T(VLOOKUP($A10,Players!$A:$E,2,FALSE)),"") | E10: 3 | F10: A
A11: Abhishek Sharma | B11: 16 | C11: Lucknow Super Giants | D11: =IFERROR(T(VLOOKUP($A11,Players!$A:$E,2,FALSE)),"") | E11: 3 | F11: A
A12: Yashasvi Jaiswal | D12: =IFERROR(T(VLOOKUP($A12,Players!$A:$E,2,FALSE)),"") | E12: 3 | F12: A
A13: Phil Salt | D13: =IFERROR(T(VLOOKUP($A13,Players!$A:$E,2,FALSE)),"") | E13: 3 | F13: A
A14: Vaibhav Suryavanshi | B14: 16.5 | C14: Kolkata Knight Riders | D14: =IFERROR(T(VLOOKUP($A14,Players!$A:$E,2,FALSE)),"") | E14: 3 | F14: A
A15: Jasprit Bumrah | B15: 24.25 | C15: Rising Pune Super Giants | D15: =IFERROR(T(VLOOKUP($A15,Players!$A:$E,2,FALSE)),"") | E15: 3 | F15: A
A16: Arshdeep Singh | D16: =IFERROR(T(VLOOKUP($A16,Players!$A:$E,2,FALSE)),"") | E16: 3 | F16: A
A17: Mohammed Siraj | B17: 14.5 | C17: Sunrisers Hydrabad | D17: =IFERROR(T(VLOOKUP($A17,Players!$A:$E,2,FALSE)),"") | E17: 3 | F17: A
A18: Varun Chakaravarthy | D18: =IFERROR(T(VLOOKUP($A18,Players!$A:$E,2,FALSE)),"") | E18: 3 | F18: A
A19: Harshal Patel | D19: =IFERROR(T(VLOOKUP($A19,Players!$A:$E,2,FALSE)),"") | E19: 3 | F19: A
A20: Noor Ahmad | D20: =IFERROR(T(VLOOKUP($A20,Players!$A:$E,2,FALSE)),"") | E20: 3 | F20: A
A21: Mitchell Starc | B21: 13 | C21: Punjab Kings | D21: =IFERROR(T(VLOOKUP($A21,Players!$A:$E,2,FALSE)),"") | E21: 3 | F21: A
A22: Trent Boult | D22: =IFERROR(T(VLOOKUP($A22,Players!$A:$E,2,FALSE)),"") | E22: 3 | F22: A
A23: Josh Hazlewood | D23: =IFERROR(T(VLOOKUP($A23,Players!$A:$E,2,FALSE)),"") | E23: 3 | F23: A
A24: Kagiso Rabada | B24: 22 | C24: Kochi Tuskers | D24: =IFERROR(T(VLOOKUP($A24,Players!$A:$E,2,FALSE)),"") | E24: 3 | F24: A
A25: Hardik Pandya | B25: 26 | C25: Guwahati Chargers | D25: =IFERROR(T(VLOOKUP($A25,Players!$A:$E,2,FALSE)),"") | E25: 3 | F25: A
A26: Sunil Narine | D26: =IFERROR(T(VLOOKUP($A26,Players!$A:$E,2,FALSE)),"") | E26: 3 | F26: A
A27: Andre Russell | D27: =IFERROR(T(VLOOKUP($A27,Players!$A:$E,2,FALSE)),"") | E27: 3 | F27: A
A28: Ravindra Jadeja | D28: =IFERROR(T(VLOOKUP($A28,Players!$A:$E,2,FALSE)),"") | E28: 3 | F28: A
A29: Axar Patel | D29: =IFERROR(T(VLOOKUP($A29,Players!$A:$E,2,FALSE)),"") | E29: 3 | F29: A
A30: Krunal Pandya | D30: =IFERROR(T(VLOOKUP($A30,Players!$A:$E,2,FALSE)),"") | E30: 3 | F30: A
A31: Nitish Kumar Reddy | D31: =IFERROR(T(VLOOKUP($A31,Players!$A:$E,2,FALSE)),"") | E31: 3 | F31: A
A32: Marcus Stoinis | D32: =IFERROR(T(VLOOKUP($A32,Players!$A:$E,2,FALSE)),"") | E32: 3 | F32: A
A33: Washington Sundar | D33: =IFERROR(T(VLOOKUP($A33,Players!$A:$E,2,FALSE)),"") | E33: 3 | F33: A
A34: Cameron Green | D34: =IFERROR(T(VLOOKUP($A34,Players!$A:$E,2,FALSE)),"") | E34: 3 | F34: A
A35: Sanju Samson | B35: 19.5 | C35: Lucknow Super Giants | D35: =IFERROR(T(VLOOKUP($A35,Players!$A:$E,2,FALSE)),"") | E35: 3 | F35: A
A36: Rishabh Pant | B36: 17 | C36: Guwahati Chargers | D36: =IFERROR(T(VLOOKUP($A36,Players!$A:$E,2,FALSE)),"") | E36: 3 | F36: A
A37: KL Rahul | B37: 29 | C37: Sunrisers Hydrabad | D37: =IFERROR(T(VLOOKUP($A37,Players!$A:$E,2,FALSE)),"") | E37: 3 | F37: A
A38: Ishan Kishan | B38: 24.5 | C38: Gujarat Titans | D38: =IFERROR(T(VLOOKUP($A38,Players!$A:$E,2,FALSE)),"") | E38: 3 | F38: A
A39: Jitesh Sharma | B39: 10.25 | C39: Punjab Kings | D39: =IFERROR(T(VLOOKUP($A39,Players!$A:$E,2,FALSE)),"") | E39: 3 | F39: A
A40: Heinrich Klaasen | B40: 30 | C40: Kochi Tuskers | D40: =IFERROR(T(VLOOKUP($A40,Players!$A:$E,2,FALSE)),"") | E40: 3 | F40: A
A41: Ruturaj Gaikwad | B41: 18.5 | C41: Chennai Super Kings | D41: =IFERROR(T(VLOOKUP($A41,Players!$A:$E,2,FALSE)),"") | E41: 2 | F41: B
...

Sheet Balance
A1: 💰 TEAM PURSE & BALANCE
A2: Rename a team here and it updates everywhere (drop-down + that team's sheet). Purse is editable per team. All figures in crores.
A3: Team | B3: Purse (Cr) | C3: Spent (Cr) | D3: Balance (Cr) | E3: Players
A4: Mumbai Indians | B4: 100 | C4: =SUMIF(Auction!$C$5:$C$1000,$A4,Auction!$B$5:$B$1000) | D4: =B4-C4 | E4: =COUNTIF(Auction!$C$5:$C$1000,$A4)
A5: Royal Challangers Banglore | B5: 100 | C5: =SUMIF(Auction!$C$5:$C$1000,$A5,Auction!$B$5:$B$1000) | D5: =B5-C5 | E5: =COUNTIF(Auction!$C$5:$C$1000,$A5)
A6: Chennai Super Kings | B6: 100 | C6: =SUMIF(Auction!$C$5:$C$1000,$A6,Auction!$B$5:$B$1000) | D6: =B6-C6 | E6: =COUNTIF(Auction!$C$5:$C$1000,$A6)
A7: Kolkata Knight Riders | B7: 100 | C7: =SUMIF(Auction!$C$5:$C$1000,$A7,Auction!$B$5:$B$1000) | D7: =B7-C7 | E7: =COUNTIF(Auction!$C$5:$C$1000,$A7)
A8: Patna Panthers | B8: 100 | C8: =SUMIF(Auction!$C$5:$C$1000,$A8,Auction!$B$5:$B$1000) | D8: =B8-C8 | E8: =COUNTIF(Auction!$C$5:$C$1000,$A8)
A9: Sunrisers Hydrabad | B9: 100 | C9: =SUMIF(Auction!$C$5:$C$1000,$A9,Auction!$B$5:$B$1000) | D9: =B9-C9 | E9: =COUNTIF(Auction!$C$5:$C$1000,$A9)
A10: Delhi Capitals | B10: 100 | C10: =SUMIF(Auction!$C$5:$C$1000,$A10,Auction!$B$5:$B$1000) | D10: =B10-C10 | E10: =COUNTIF(Auction!$C$5:$C$1000,$A10)
A11: Gujarat Titans | B11: 100 | C11: =SUMIF(Auction!$C$5:$C$1000,$A11,Auction!$B$5:$B$1000) | D11: =B11-C11 | E11: =COUNTIF(Auction!$C$5:$C$1000,$A11)
A12: Lucknow Super Giants | B12: 100 | C12: =SUMIF(Auction!$C$5:$C$1000,$A12,Auction!$B$5:$B$1000) | D12: =B12-C12 | E12: =COUNTIF(Auction!$C$5:$C$1000,$A12)
A13: Imphal Igniter | B13: 100 | C13: =SUMIF(Auction!$C$5:$C$1000,$A13,Auction!$B$5:$B$1000) | D13: =B13-C13 | E13: =COUNTIF(Auction!$C$5:$C$1000,$A13)
A14: Punjab Kings | B14: 100 | C14: =SUMIF(Auction!$C$5:$C$1000,$A14,Auction!$B$5:$B$1000) | D14: =B14-C14 | E14: =COUNTIF(Auction!$C$5:$C$1000,$A14)
A15: Rising Pune Super Giants | B15: 100 | C15: =SUMIF(Auction!$C$5:$C$1000,$A15,Auction!$B$5:$B$1000) | D15: =B15-C15 | E15: =COUNTIF(Auction!$C$5:$C$1000,$A15)
... A18: Guwahati Chargers | B18: 100 | C18: =SUMIF(Auction!$C$5:$C$1000,$A18,Auction!$B$5:$B$1000) | D18: =B18-C18 | E18: =COUNTIF(Auction!$C$5:$C$1000,$A18)
A19: TOTAL | B19: =SUM(B4:B18) | C19: =SUM(C4:C18) | D19: =SUM(D4:D18) | E19: =SUM(E4:E18)

Sheet Summary
B2: =Balance!$A$4 | F2: =Balance!$A$5 | J2: =Balance!$A$6 | N2: =Balance!$A$7 | R2: =Balance!$A$8
B3: S.No | C3: Player Name | D3: Amount | F3: S.No | G3: Player Name | H3: Amount | J3: S.No | K3: Player Name | L3: Amount | N3: S.No | O3: Player Name | P3: Amount | R3: S.No | S3: Player Name | T3: Amount
B4: 1 | C4: {=IFERROR(INDEX(Auction!$A$5:$A$1000,SMALL(IF(Auction!$C$5:$C$1000=$B$2,ROW(Auction!$C$5:$C$1000)-ROW(Auction!$C$5)+1),1)),"")} | D4: {=IFERROR(INDEX(Auction!$B$5:$B$1000,SMALL(IF(Auction!$C$5:$C$1000=$B$2,ROW(Auction!$C$5:$C$1000)-ROW(Auction!$C$5)+1),1)),"")} | F4: 1 | G4: {=IFERROR(INDEX(Auction!$A$5:$A$1000,SMALL(IF(Auction!$C$5:$C$1000=$F$2,ROW(Auction!$C$5:$C$1000)-ROW(Auction!$C$5)+1),1)),"")} | H4: {=IFERROR(INDEX(Auction!$B$5:$B$1000,SMALL(IF(Auction!$C$5:$C$1000=$F$2,ROW(Auction!$C$5:$C$1000)-ROW(Auction!$C$5)+1),1)),"")} | J4: 1 | K4: {=IFERROR(INDEX(Auction!$A$5:$A$1000,SMALL(IF(Auction!$C$5:$C$1000=$J$2,ROW(Auction!$C$5:$C$1000)-ROW(Auction!$C$5)+1),1)),"")} | L4: {=IFERROR(INDEX(Auction!$B$5:$B$1000,SMALL(IF(Auction!$C$5:$C$1000=$J$2,ROW(Auction!$C$5:$C$1000)-ROW(Auction!$C$5)+1),1)),"")} | N4: 1 | O4: {=IFERROR(INDEX(Auction!$A$5:$A$1000,SMALL(IF(Auction!$C$5:$C$1000=$N$2,ROW(Auction!$C$5:$C$1000)-ROW(Auction!$C$5)+1),1)),"")} | P4: {=IFERROR(INDEX(Auction!$B$5:$B$1000,SMALL(IF(Auction!$C$5:$C$1000=$N$2,ROW(Auction!$C$5:$C$1000)-ROW(Auction!$C$5)+1),1)),"")} | R4: 1 | S4: {=IFERROR(INDEX(Auction!$A$5:$A$1000,SMALL(IF(Auction!$C$5:$C$1000=$R$2,ROW(Auction!$C$5:$C$1000)-ROW(Auction!$C$5)+1),1)),"")} | T4: {=IFERROR(INDEX(Auction!$B$5:$B$1000,SMALL(IF(Auction!$C$5:$C$1000=$R$2,ROW(Auction!$C$5:$C$1000)-ROW(Auction!$C$5)+1),1)),"")}
B5: 2 | C5: {=IFERROR(INDEX(Auction!$A$5:$A$1000,SMALL(IF(Auction!$C$5:$C$1000=$B$2,ROW(Auction!$C$5:$C$1000)-ROW(Auction!$C$5)+1),2)),"")} | D5: {=IFERROR(INDEX(Auction!$B$5:$B$1000,SMALL(IF(Auction!$C$5:$C$1000=$B$2,ROW(Auction!$C$5:$C$1000)-ROW(Auction!$C$5)+1),2)),"")} | F5: 2 | G5: {=IFERROR(INDEX(Auction!$A$5:$A$1000,SMALL(IF(Auction!$C$5:$C$1000=$F$2,ROW(Auction!$C$5:$C$1000)-ROW(Auction!$C$5)+1),2)),"")} | H5: {=IFERROR(INDEX(Auction!$B$5:$B$1000,SMALL(IF(Auction!$C$5:$C$1000=$F$2,ROW(Auction!$C$5:$C$1000)-ROW(Auction!$C$5)+1),2)),"")} | J5: 2 | K5: {=IFERROR(INDEX(Auction!$A$5:$A$1000,SMALL(IF(Auction!$C$5:$C$1000=$J$2,ROW(Auction!$C$5:$C$1000)-ROW(Auction!$C$5)+1),2)),"")} | L5: {=IFERROR(INDEX(Auction!$B$5:$B$1000,SMALL(IF(Auction!$C$5:$C$1000=$J$2,ROW(Auction!$C$5:$C$1000)-ROW(Auction!$C$5)+1),2)),"")} | N5: 2 | O5: {=IFERROR(INDEX(Auction!$A$5:$A$1000,SMALL(IF(Auction!$C$5:$C$1000=$N$2,ROW(Auction!$C$5:$C$1000)-ROW(Auction!$C$5)+1),2)),"")} | P5: {=IFERROR(INDEX(Auction!$B$5:$B$1000,SMALL(IF(Auction!$C$5:$C$1000=$N$2,ROW(Auction!$C$5:$C$1000)-ROW(Auction!$C$5)+1),2)),"")} | R5: 2 | S5: {=IFERROR(INDEX(Auction!$A$5:$A$1000,SMALL(IF(Auction!$C$5:$C$1000=$R$2,ROW(Auction!$C$5:$C$1000)-ROW(Auction!$C$5)+1),2)),"")} | T5: {=IFERROR(INDEX(Auction!$B$5:$B$1000,SMALL(IF(Auction!$C$5:$C$1000=$R$2,ROW(Auction!$C$5:$C$1000)-ROW(Auction!$C$5)+1),2)),"")}
B6: 3 | C6: {=IFERROR(INDEX(Auction!$A$5:$A$1000,SMALL(IF(Auction!$C$5:$C$1000=$B$2,ROW(Auction!$C$5:$C$1000)-ROW(Auction!$C$5)+1),3)),"")} | D6: {=IFERROR(INDEX(Auction!$B$5:$B$1000,SMALL(IF(Auction!$C$5:$C$1000=$B$2,ROW(Auction!$C$5:$C$1000)-ROW(Auction!$C$5)+1),3)),"")} | F6: 3 | G6: {=IFERROR(INDEX(Auction!$A$5:$A$1000,SMALL(IF(Auction!$C$5:$C$1000=$F$2,ROW(Auction!$C$5:$C$1000)-ROW(Auction!$C$5)+1),3)),"")} | H6: {=IFERROR(INDEX(Auction!$B$5:$B$1000,SMALL(IF(Auction!$C$5:$C$1000=$F$2,ROW(Auction!$C$5:$C$1000)-ROW(Auction!$C$5)+1),3)),"")} | J6: 3 | K6: {=IFERROR(INDEX(Auction!$A$5:$A$1000,SMALL(IF(Auction!$C$5:$C$1000=$J$2,ROW(Auction!$C$5:$C$1000)-ROW(Auction!$C$5)+1),3)),"")} | L6: {=IFERROR(INDEX(Auction!$B$5:$B$1000,SMALL(IF(Auction!$C$5:$C$1000=$J$2,ROW(Auction!$C$5:$C$1000)-ROW(Auction!$C$5)+1),3)),"")} | N6: 3 | O6: {=IFERROR(INDEX(Auction!$A$5:$A$1000,SMALL(IF(Auction!$C$5:$C$1000=$N$2,ROW(Auction!$C$5:$C$1000)-ROW(Auction!$C$5)+1),3)),"")} | P6: {=IFERROR(INDEX(Auction!$B$5:$B$1000,SMALL(IF(Auction!$C$5:$C$1000=$N$2,ROW(Auction!$C$5:$C$1000)-ROW(Auction!$C$5)+1),3)),"")} | R6: 3 | S6: {=IFERROR(INDEX(Auction!$A$5:$A$1000,SMALL(IF(Auction!$C$5:$C$1000=$R$2,ROW(Auction!$C$5:$C$1000)-ROW(Auction!$C$5)+1),3)),"")} | T6: {=IFERROR(INDEX(Auction!$B$5:$B$1000,SMALL(IF(Auction!$C$5:$C$1000=$R$2,ROW(Auction!$C$5:$C$1000)-ROW(Auction!$C$5)+1),3)),"")}
B7: 4 | C7: {=IFERROR(INDEX(Auction!$A$5:$A$1000,SMALL(IF(Auction!$C$5:$C$1000=$B$2,ROW(Auction!$C$5:$C$1000)-ROW(Auction!$C$5)+1),4)),"")} | D7: {=IFERROR(INDEX(Auction!$B$5:$B$1000,SMALL(IF(Auction!$C$5:$C$1000=$B$2,ROW(Auction!$C$5:$C$1000)-ROW(Auction!$C$5)+1),4)),"")} | F7: 4 | G7: {=IFERROR(INDEX(Auction!$A$5:$A$1000,SMALL(IF(Auction!$C$5:$C$1000=$F$2,ROW(Auction!$C$5:$C$1000)-ROW(Auction!$C$5)+1),4)),"")} | H7: {=IFERROR(INDEX(Auction!$B$5:$B$1000,SMALL(IF(Auction!$C$5:$C$1000=$F$2,ROW(Auction!$C$5:$C$1000)-ROW(Auction!$C$5)+1),4)),"")} | J7: 4 | K7: {=IFERROR(INDEX(Auction!$A$5:$A$1000,SMALL(IF(Auction!$C$5:$C$1000=$J$2,ROW(Auction!$C$5:$C$1000)-ROW(Auction!$C$5)+1),4)),"")} | L7: {=IFERROR(INDEX(Auction!$B$5:$B$1000,SMALL(IF(Auction!$C$5:$C$1000=$J$2,ROW(Auction!$C$5:$C$1000)-ROW(Auction!$C$5)+1),4)),"")} | N7: 4 | O7: {=IFERROR(INDEX(Auction!$A$5:$A$1000,SMALL(IF(Auction!$C$5:$C$1000=$N$2,ROW(Auction!$C$5:$C$1000)-ROW(Auction!$C$5)+1),4)),"")} | P7: {=IFERROR(INDEX(Auction!$B$5:$B$1000,SMALL(IF(Auction!$C$5:$C$1000=$N$2,ROW(Auction!$C$5:$C$1000)-ROW(Auction!$C$5)+1),4)),"")} | R7: 4 | S7: {=IFERROR(INDEX(Auction!$A$5:$A$1000,SMALL(IF(Auction!$C$5:$C$1000=$R$2,ROW(Auction!$C$5:$C$1000)-ROW(Auction!$C$5)+1),4)),"")} | T7: {=IFERROR(INDEX(Auction!$B$5:$B$1000,SMALL(IF(Auction!$C$5:$C$1000=$R$2,ROW(Auction!$C$5:$C$1000)-ROW(Auction!$C$5)+1),4)),"")}
B8: 5 | C8: {=IFERROR(INDEX(Auction!$A$5:$A$1000,SMALL(IF(Auction!$C$5:$C$1000=$B$2,ROW(Auction!$C$5:$C$1000)-ROW(Auction!$C$5)+1),5)),"")} | D8: {=IFERROR(INDEX(Auction!$B$5:$B$1000,SMALL(IF(Auction!$C$5:$C$1000=$B$2,ROW(Auction!$C$5:$C$1000)-ROW(Auction!$C$5)+1),5)),"")} | F8: 5 | G8: {=IFERROR(INDEX(Auction!$A$5:$A$1000,SMALL(IF(Auction!$C$5:$C$1000=$F$2,ROW(Auction!$C$5:$C$1000)-ROW(Auction!$C$5)+1),5)),"")} | H8: {=IFERROR(INDEX(Auction!$B$5:$B$1000,SMALL(IF(Auction!$C$5:$C$1000=$F$2,ROW(Auction!$C$5:$C$1000)-ROW(Auction!$C$5)+1),5)),"")} | J8: 5 | K8: {=IFERROR(INDEX(Auction!$A$5:$A$1000,SMALL(IF(Auction!$C$5:$C$1000=$J$2,ROW(Auction!$C$5:$C$1000)-ROW(Auction!$C$5)+1),5)),"")} | L8: {=IFERROR(INDEX(Auction!$B$5:$B$1000,SMALL(IF(Auction!$C$5:$C$1000=$J$2,ROW(Auction!$C$5:$C$1000)-ROW(Auction!$C$5)+1),5)),"")} | N8: 5 | O8: {=IFERROR(INDEX(Auction!$A$5:$A$1000,SMALL(IF(Auction!$C$5:$C$1000=$N$2,ROW(Auction!$C$5:$C$1000)-ROW(Auction!$C$5)+1),5)),"")} | P8: {=IFERROR(INDEX(Auction!$B$5:$B$1000,SMALL(IF(Auction!$C$5:$C$1000=$N$2,ROW(Auction!$C$5:$C$1000)-ROW(Auction!$C$5)+1),5)),"")} | R8: 5 | S8: {=IFERROR(INDEX(Auction!$A$5:$A$1000,SMALL(IF(Auction!$C$5:$C$1000=$R$2,ROW(Auction!$C$5:$C$1000)-ROW(Auction!$C$5)+1),5)),"")} | T8: {=IFERROR(INDEX(Auction!$B$5:$B$1000,SMALL(IF(Auction!$C$5:$C$1000=$R$2,ROW(Auction!$C$5:$C$1000)-ROW(Auction!$C$5)+1),5)),"")}
B9: 6 | C9: {=IFERROR(INDEX(Auction!$A$5:$A$1000,SMALL(IF(Auction!$C$5:$C$1000=$B$2,ROW(Auction!$C$5:$C$1000)-ROW(Auction!$C$5)+1),6)),"")} | D9: {=IFERROR(INDEX(Auction!$B$5:$B$1000,SMALL(IF(Auction!$C$5:$C$1000=$B$2,ROW(Auction!$C$5:$C$1000)-ROW(Auction!$C$5)+1),6)),"")} | F9: 6 | G9: {=IFERROR(INDEX(Auction!$A$5:$A$1000,SMALL(IF(Auction!$C$5:$C$1000=$F$2,ROW(Auction!$C$5:$C$1000)-ROW(Auction!$C$5)+1),6)),"")} | H9: {=IFERROR(INDEX(Auction!$B$5:$B$1000,SMALL(IF(Auction!$C$5:$C$1000=$F$2,ROW(Auction!$C$5:$C$1000)-ROW(Auction!$C$5)+1),6)),"")} | J9: 6 | K9: {=IFERROR(INDEX(Auction!$A$5:$A$1000,SMALL(IF(Auction!$C$5:$C$1000=$J$2,ROW(Auction!$C$5:$C$1000)-ROW(Auction!$C$5)+1),6)),"")} | L9: {=IFERROR(INDEX(Auction!$B$5:$B$1000,SMALL(IF(Auction!$C$5:$C$1000=$J$2,ROW(Auction!$C$5:$C$1000)-ROW(Auction!$C$5)+1),6)),"")} | N9: 6 | O9: {=IFERROR(INDEX(Auction!$A$5:$A$1000,SMALL(IF(Auction!$C$5:$C$1000=$N$2,ROW(Auction!$C$5:$C$1000)-ROW(Auction!$C$5)+1),6)),"")} | P9: {=IFERROR(INDEX(Auction!$B$5:$B$1000,SMALL(IF(Auction!$C$5:$C$1000=$N$2,ROW(Auction!$C$5:$C$1000)-ROW(Auction!$C$5)+1),6)),"")} | R9: 6 | S9: {=IFERROR(INDEX(Auction!$A$5:$A$1000,SMALL(IF(Auction!$C$5:$C$1000=$R$2,ROW(Auction!$C$5:$C$1000)-ROW(Auction!$C$5)+1),6)),"")} | T9: {=IFERROR(INDEX(Auction!$B$5:$B$1000,SMALL(IF(Auction!$C$5:$C$1000=$R$2,ROW(Auction!$C$5:$C$1000)-ROW(Auction!$C$5)+1),6)),"")}
B10: 7 | C10: {=IFERROR(INDEX(Auction!$A$5:$A$1000,SMALL(IF(Auction!$C$5:$C$1000=$B$2,ROW(Auction!$C$5:$C$1000)-ROW(Auction!$C$5)+1),7)),"")} | D10: {=IFERROR(INDEX(Auction!$B$5:$B$1000,SMALL(IF(Auction!$C$5:$C$1000=$B$2,ROW(Auction!$C$5:$C$1000)-ROW(Auction!$C$5)+1),7)),"")} | F10: 7 | G10: {=IFERROR(INDEX(Auction!$A$5:$A$1000,SMALL(IF(Auction!$C$5:$C$1000=$F$2,ROW(Auction!$C$5:$C$1000)-ROW(Auction!$C$5)+1),7)),"")} | H10: {=IFERROR(INDEX(Auction!$B$5:$B$1000,SMALL(IF(Auction!$C$5:$C$1000=$F$2,ROW(Auction!$C$5:$C$1000)-ROW(Auction!$C$5)+1),7)),"")} | J10: 7 | K10: {=IFERROR(INDEX(Auction!$A$5:$A$1000,SMALL(IF(Auction!$C$5:$C$1000=$J$2,ROW(Auction!$C$5:$C$1000)-ROW(Auction!$C$5)+1),7)),"")} | L10: {=IFERROR(INDEX(Auction!$B$5:$B$1000,SMALL(IF(Auction!$C$5:$C$1000=$J$2,ROW(Auction!$C$5:$C$1000)-ROW(Auction!$C$5)+1),7)),"")} | N10: 7 | O10: {=IFERROR(INDEX(Auction!$A$5:$A$1000,SMALL(IF(Auction!$C$5:$C$1000=$N$2,ROW(Auction!$C$5:$C$1000)-ROW(Auction!$C$5)+1),7)),"")} | P10: {=IFERROR(INDEX(Auction!$B$5:$B$1000,SMALL(IF(Auction!$C$5:$C$1000=$N$2,ROW(Auction!$C$5:$C$1000)-ROW(Auction!$C$5)+1),7)),"")} | R10: 7 | S10: {=IFERROR(INDEX(Auction!$A$5:$A$1000,SMALL(IF(Auction!$C$5:$C$1000=$R$2,ROW(Auction!$C$5:$C$1000)-ROW(Auction!$C$5)+1),7)),"")} | T10: {=IFERROR(INDEX(Auction!$B$5:$B$1000,SMALL(IF(Auction!$C$5:$C$1000=$R$2,ROW(Auction!$C$5:$C$1000)-ROW(Auction!$C$5)+1),7)),"")}
B11: 8 | C11: {=IFERROR(INDEX(Auction!$A$5:$A$1000,SMALL(IF(Auction!$C$5:$C$1000=$B$2,ROW(Auction!$C$5:$C$1000)-ROW(Auction!$C$5)+1),8)),"")} | D11: {=IFERROR(INDEX(Auction!$B$5:$B$1000,SMALL(IF(Auction!$C$5:$C$1000=$B$2,ROW(Auction!$C$5:$C$1000)-ROW(Auction!$C$5)+1),8)),"")} | F11: 8 | G11: {=IFERROR(INDEX(Auction!$A$5:$A$1000,SMALL(IF(Auction!$C$5:$C$1000=$F$2,ROW(Auction!$C$5:$C$1000)-ROW(Auction!$C$5)+1),8)),"")} | H11: {=IFERROR(INDEX(Auction!$B$5:$B$1000,SMALL(IF(Auction!$C$5:$C$1000=$F$2,ROW(Auction!$C$5:$C$1000)-ROW(Auction!$C$5)+1),8)),"")} | J11: 8 | K11: {=IFERROR(INDEX(Auction!$A$5:$A$1000,SMALL(IF(Auction!$C$5:$C$1000=$J$2,ROW(Auction!$C$5:$C$1000)-ROW(Auction!$C$5)+1),8)),"")} | L11: {=IFERROR(INDEX(Auction!$B$5:$B$1000,SMALL(IF(Auction!$C$5:$C$1000=$J$2,ROW(Auction!$C$5:$C$1000)-ROW(Auction!$C$5)+1),8)),"")} | N11: 8 | O11: {=IFERROR(INDEX(Auction!$A$5:$A$1000,SMALL(IF(Auction!$C$5:$C$1000=$N$2,ROW(Auction!$C$5:$C$1000)-ROW(Auction!$C$5)+1),8)),"")} | P11: {=IFERROR(INDEX(Auction!$B$5:$B$1000,SMALL(IF(Auction!$C$5:$C$1000=$N$2,ROW(Auction!$C$5:$C$1000)-ROW(Auction!$C$5)+1),8)),"")} | R11: 8 | S11: {=IFERROR(INDEX(Auction!$A$5:$A$1000,SMALL(IF(Auction!$C$5:$C$1000=$R$2,ROW(Auction!$C$5:$C$1000)-ROW(Auction!$C$5)+1),8)),"")} | T11: {=IFERROR(INDEX(Auction!$B$5:$B$1000,SMALL(IF(Auction!$C$5:$C$1000=$R$2,ROW(Auction!$C$5:$C$1000)-ROW(Auction!$C$5)+1),8)),"")}
B12: 9 | C12: {=IFERROR(INDEX(Auction!$A$5:$A$1000,SMALL(IF(Auction!$C$5:$C$1000=$B$2,ROW(Auction!$C$5:$C$1000)-ROW(Auction!$C$5)+1),9)),"")} | D12: {=IFERROR(INDEX(Auction!$B$5:$B$1000,SMALL(IF(Auction!$C$5:$C$1000=$B$2,ROW(Auction!$C$5:$C$1000)-ROW(Auction!$C$5)+1),9)),"")} | F12: 9 | G12: {=IFERROR(INDEX(Auction!$A$5:$A$1000,SMALL(IF(Auction!$C$5:$C$1000=$F$2,ROW(Auction!$C$5:$C$1000)-ROW(Auction!$C$5)+1),9)),"")} | H12: {=IFERROR(INDEX(Auction!$B$5:$B$1000,SMALL(IF(Auction!$C$5:$C$1000=$F$2,ROW(Auction!$C$5:$C$1000)-ROW(Auction!$C$5)+1),9)),"")} | J12: 9 | K12: {=IFERROR(INDEX(Auction!$A$5:$A$1000,SMALL(IF(Auction!$C$5:$C$1000=$J$2,ROW(Auction!$C$5:$C$1000)-ROW(Auction!$C$5)+1),9)),"")} | L12: {=IFERROR(INDEX(Auction!$B$5:$B$1000,SMALL(IF(Auction!$C$5:$C$1000=$J$2,ROW(Auction!$C$5:$C$1000)-ROW(Auction!$C$5)+1),9)),"")} | N12: 9 | O12: {=IFERROR(INDEX(Auction!$A$5:$A$1000,SMALL(IF(Auction!$C$5:$C$1000=$N$2,ROW(Auction!$C$5:$C$1000)-ROW(Auction!$C$5)+1),9)),"")} | P12: {=IFERROR(INDEX(Auction!$B$5:$B$1000,SMALL(IF(Auction!$C$5:$C$1000=$N$2,ROW(Auction!$C$5:$C$1000)-ROW(Auction!$C$5)+1),9)),"")} | R12: 9 | S12: {=IFERROR(INDEX(Auction!$A$5:$A$1000,SMALL(IF(Auction!$C$5:$C$1000=$R$2,ROW(Auction!$C$5:$C$1000)-ROW(Auction!$C$5)+1),9)),"")} | T12: {=IFERROR(INDEX(Auction!$B$5:$B$1000,SMALL(IF(Auction!$C$5:$C$1000=$R$2,ROW(Auction!$C$5:$C$1000)-ROW(Auction!$C$5)+1),9)),"")}
B13: 10 | C13: {=IFERROR(INDEX(Auction!$A$5:$A$1000,SMALL(IF(Auction!$C$5:$C$1000=$B$2,ROW(Auction!$C$5:$C$1000)-ROW(Auction!$C$5)+1),10)),"")} | D13: {=IFERROR(INDEX(Auction!$B$5:$B$1000,SMALL(IF(Auction!$C$5:$C$1000=$B$2,ROW(Auction!$C$5:$C$1000)-ROW(Auction!$C$5)+1),10)),"")} | F13: 10 | G13: {=IFERROR(INDEX(Auction!$A$5:$A$1000,SMALL(IF(Auction!$C$5:$C$1000=$F$2,ROW(Auction!$C$5:$C$1000)-ROW(Auction!$C$5)+1),10)),"")} | H13: {=IFERROR(INDEX(Auction!$B$5:$B$1000,SMALL(IF(Auction!$C$5:$C$1000=$F$2,ROW(Auction!$C$5:$C$1000)-ROW(Auction!$C$5)+1),10)),"")} | J13: 10 | K13: {=IFERROR(INDEX(Auction!$A$5:$A$1000,SMALL(IF(Auction!$C$5:$C$1000=$J$2,ROW(Auction!$C$5:$C$1000)-ROW(Auction!$C$5)+1),10)),"")} | L13: {=IFERROR(INDEX(Auction!$B$5:$B$1000,SMALL(IF(Auction!$C$5:$C$1000=$J$2,ROW(Auction!$C$5:$C$1000)-ROW(Auction!$C$5)+1),10)),"")} | N13: 10 | O13: {=IFERROR(INDEX(Auction!$A$5:$A$1000,SMALL(IF(Auction!$C$5:$C$1000=$N$2,ROW(Auction!$C$5:$C$1000)-ROW(Auction!$C$5)+1),10)),"")} | P13: {=IFERROR(INDEX(Auction!$B$5:$B$1000,SMALL(IF(Auction!$C$5:$C$1000=$N$2,ROW(Auction!$C$5:$C$1000)-ROW(Auction!$C$5)+1),10)),"")} | R13: 10 | S13: {=IFERROR(INDEX(Auction!$A$5:$A$1000,SMALL(IF(Auction!$C$5:$C$1000=$R$2,ROW(Auction!$C$5:$C$1000)-ROW(Auction!$C$5)+1),10)),"")} | T13: {=IFERROR(INDEX(Auction!$B$5:$B$1000,SMALL(IF(Auction!$C$5:$C$1000=$R$2,ROW(Auction!$C$5:$C$1000)-ROW(Auction!$C$5)+1),10)),"")}
B14: 11 | C14: {=IFERROR(INDEX(Auction!$A$5:$A$1000,SMALL(IF(Auction!$C$5:$C$1000=$B$2,ROW(Auction!$C$5:$C$1000)-ROW(Auction!$C$5)+1),11)),"")} | D14: {=IFERROR(INDEX(Auction!$B$5:$B$1000,SMALL(IF(Auction!$C$5:$C$1000=$B$2,ROW(Auction!$C$5:$C$1000)-ROW(Auction!$C$5)+1),11)),"")} | F14: 11 | G14: {=IFERROR(INDEX(Auction!$A$5:$A$1000,SMALL(IF(Auction!$C$5:$C$1000=$F$2,ROW(Auction!$C$5:$C$1000)-ROW(Auction!$C$5)+1),11)),"")} | H14: {=IFERROR(INDEX(Auction!$B$5:$B$1000,SMALL(IF(Auction!$C$5:$C$1000=$F$2,ROW(Auction!$C$5:$C$1000)-ROW(Auction!$C$5)+1),11)),"")} | J14: 11 | K14: {=IFERROR(INDEX(Auction!$A$5:$A$1000,SMALL(IF(Auction!$C$5:$C$1000=$J$2,ROW(Auction!$C$5:$C$1000)-ROW(Auction!$C$5)+1),11)),"")} | L14: {=IFERROR(INDEX(Auction!$B$5:$B$1000,SMALL(IF(Auction!$C$5:$C$1000=$J$2,ROW(Auction!$C$5:$C$1000)-ROW(Auction!$C$5)+1),11)),"")} | N14: 11 | O14: {=IFERROR(INDEX(Auction!$A$5:$A$1000,SMALL(IF(Auction!$C$5:$C$1000=$N$2,ROW(Auction!$C$5:$C$1000)-ROW(Auction!$C$5)+1),11)),"")} | P14: {=IFERROR(INDEX(Auction!$B$5:$B$1000,SMALL(IF(Auction!$C$5:$C$1000=$N$2,ROW(Auction!$C$5:$C$1000)-ROW(Auction!$C$5)+1),11)),"")} | R14: 11 | S14: {=IFERROR(INDEX(Auction!$A$5:$A$1000,SMALL(IF(Auction!$C$5:$C$1000=$R$2,ROW(Auction!$C$5:$C$1000)-ROW(Auction!$C$5)+1),11)),"")} | T14: {=IFERROR(INDEX(Auction!$B$5:$B$1000,SMALL(IF(Auction!$C$5:$C$1000=$R$2,ROW(Auction!$C$5:$C$1000)-ROW(Auction!$C$5)+1),11)),"")}
B15: 12 | C15: {=IFERROR(INDEX(Auction!$A$5:$A$1000,SMALL(IF(Auction!$C$5:$C$1000=$B$2,ROW(Auction!$C$5:$C$1000)-ROW(Auction!$C$5)+1),12)),"")} | D15: {=IFERROR(INDEX(Auction!$B$5:$B$1000,SMALL(IF(Auction!$C$5:$C$1000=$B$2,ROW(Auction!$C$5:$C$1000)-ROW(Auction!$C$5)+1),12)),"")} | F15: 12 | G15: {=IFERROR(INDEX(Auction!$A$5:$A$1000,SMALL(IF(Auction!$C$5:$C$1000=$F$2,ROW(Auction!$C$5:$C$1000)-ROW(Auction!$C$5)+1),12)),"")} | H15: {=IFERROR(INDEX(Auction!$B$5:$B$1000,SMALL(IF(Auction!$C$5:$C$1000=$F$2,ROW(Auction!$C$5:$C$1000)-ROW(Auction!$C$5)+1),12)),"")} | J15: 12 | K15: {=IFERROR(INDEX(Auction!$A$5:$A$1000,SMALL(IF(Auction!$C$5:$C$1000=$J$2,ROW(Auction!$C$5:$C$1000)-ROW(Auction!$C$5)+1),12)),"")} | L15: {=IFERROR(INDEX(Auction!$B$5:$B$1000,SMALL(IF(Auction!$C$5:$C$1000=$J$2,ROW(Auction!$C$5:$C$1000)-ROW(Auction!$C$5)+1),12)),"")} | N15: 12 | O15: {=IFERROR(INDEX(Auction!$A$5:$A$1000,SMALL(IF(Auction!$C$5:$C$1000=$N$2,ROW(Auction!$C$5:$C$1000)-ROW(Auction!$C$5)+1),12)),"")} | P15: {=IFERROR(INDEX(Auction!$B$5:$B$1000,SMALL(IF(Auction!$C$5:$C$1000=$N$2,ROW(Auction!$C$5:$C$1000)-ROW(Auction!$C$5)+1),12)),"")} | R15: 12 | S15: {=IFERROR(INDEX(Auction!$A$5:$A$1000,SMALL(IF(Auction!$C$5:$C$1000=$R$2,ROW(Auction!$C$5:$C$1000)-ROW(Auction!$C$5)+1),12)),"")} | T15: {=IFERROR(INDEX(Auction!$B$5:$B$1000,SMALL(IF(Auction!$C$5:$C$1000=$R$2,ROW(Auction!$C$5:$C$1000)-ROW(Auction!$C$5)+1),12)),"")}
B16: 13 | C16: {=IFERROR(INDEX(Auction!$A$5:$A$1000,SMALL(IF(Auction!$C$5:$C$1000=$B$2,ROW(Auction!$C$5:$C$1000)-ROW(Auction!$C$5)+1),13)),"")} | D16: {=IFERROR(INDEX(Auction!$B$5:$B$1000,SMALL(IF(Auction!$C$5:$C$1000=$B$2,ROW(Auction!$C$5:$C$1000)-ROW(Auction!$C$5)+1),13)),"")} | F16: 13 | G16: {=IFERROR(INDEX(Auction!$A$5:$A$1000,SMALL(IF(Auction!$C$5:$C$1000=$F$2,ROW(Auction!$C$5:$C$1000)-ROW(Auction!$C$5)+1),13)),"")} | H16: {=IFERROR(INDEX(Auction!$B$5:$B$1000,SMALL(IF(Auction!$C$5:$C$1000=$F$2,ROW(Auction!$C$5:$C$1000)-ROW(Auction!$C$5)+1),13)),"")} | J16: 13 | K16: {=IFERROR(INDEX(Auction!$A$5:$A$1000,SMALL(IF(Auction!$C$5:$C$1000=$J$2,ROW(Auction!$C$5:$C$1000)-ROW(Auction!$C$5)+1),13)),"")} | L16: {=IFERROR(INDEX(Auction!$B$5:$B$1000,SMALL(IF(Auction!$C$5:$C$1000=$J$2,ROW(Auction!$C$5:$C$1000)-ROW(Auction!$C$5)+1),13)),"")} | N16: 13 | O16: {=IFERROR(INDEX(Auction!$A$5:$A$1000,SMALL(IF(Auction!$C$5:$C$1000=$N$2,ROW(Auction!$C$5:$C$1000)-ROW(Auction!$C$5)+1),13)),"")} | P16: {=IFERROR(INDEX(Auction!$B$5:$B$1000,SMALL(IF(Auction!$C$5:$C$1000=$N$2,ROW(Auction!$C$5:$C$1000)-ROW(Auction!$C$5)+1),13)),"")} | R16: 13 | S16: {=IFERROR(INDEX(Auction!$A$5:$A$1000,SMALL(IF(Auction!$C$5:$C$1000=$R$2,ROW(Auction!$C$5:$C$1000)-ROW(Auction!$C$5)+1),13)),"")} | T16: {=IFERROR(INDEX(Auction!$B$5:$B$1000,SMALL(IF(Auction!$C$5:$C$1000=$R$2,ROW(Auction!$C$5:$C$1000)-ROW(Auction!$C$5)+1),13)),"")}
B17: 14 | C17: {=IFERROR(INDEX(Auction!$A$5:$A$1000,SMALL(IF(Auction!$C$5:$C$1000=$B$2,ROW(Auction!$C$5:$C$1000)-ROW(Auction!$C$5)+1),14)),"")} | D17: {=IFERROR(INDEX(Auction!$B$5:$B$1000,SMALL(IF(Auction!$C$5:$C$1000=$B$2,ROW(Auction!$C$5:$C$1000)-ROW(Auction!$C$5)+1),14)),"")} | F17: 14 | G17: {=IFERROR(INDEX(Auction!$A$5:$A$1000,SMALL(IF(Auction!$C$5:$C$1000=$F$2,ROW(Auction!$C$5:$C$1000)-ROW(Auction!$C$5)+1),14)),"")} | H17: {=IFERROR(INDEX(Auction!$B$5:$B$1000,SMALL(IF(Auction!$C$5:$C$1000=$F$2,ROW(Auction!$C$5:$C$1000)-ROW(Auction!$C$5)+1),14)),"")} | J17: 14 | K17: {=IFERROR(INDEX(Auction!$A$5:$A$1000,SMALL(IF(Auction!$C$5:$C$1000=$J$2,ROW(Auction!$C$5:$C$1000)-ROW(Auction!$C$5)+1),14)),"")} | L17: {=IFERROR(INDEX(Auction!$B$5:$B$1000,SMALL(IF(Auction!$C$5:$C$1000=$J$2,ROW(Auction!$C$5:$C$1000)-ROW(Auction!$C$5)+1),14)),"")} | N17: 14 | O17: {=IFERROR(INDEX(Auction!$A$5:$A$1000,SMALL(IF(Auction!$C$5:$C$1000=$N$2,ROW(Auction!$C$5:$C$1000)-ROW(Auction!$C$5)+1),14)),"")} | P17: {=IFERROR(INDEX(Auction!$B$5:$B$1000,SMALL(IF(Auction!$C$5:$C$1000=$N$2,ROW(Auction!$C$5:$C$1000)-ROW(Auction!$C$5)+1),14)),"")} | R17: 14 | S17: {=IFERROR(INDEX(Auction!$A$5:$A$1000,SMALL(IF(Auction!$C$5:$C$1000=$R$2,ROW(Auction!$C$5:$C$1000)-ROW(Auction!$C$5)+1),14)),"")} | T17: {=IFERROR(INDEX(Auction!$B$5:$B$1000,SMALL(IF(Auction!$C$5:$C$1000=$R$2,ROW(Auction!$C$5:$C$1000)-ROW(Auction!$C$5)+1),14)),"")}
B18: 15 | C18: {=IFERROR(INDEX(Auction!$A$5:$A$1000,SMALL(IF(Auction!$C$5:$C$1000=$B$2,ROW(Auction!$C$5:$C$1000)-ROW(Auction!$C$5)+1),15)),"")} | D18: {=IFERROR(INDEX(Auction!$B$5:$B$1000,SMALL(IF(Auction!$C$5:$C$1000=$B$2,ROW(Auction!$C$5:$C$1000)-ROW(Auction!$C$5)+1),15)),"")} | F18: 15 | G18: {=IFERROR(INDEX(Auction!$A$5:$A$1000,SMALL(IF(Auction!$C$5:$C$1000=$F$2,ROW(Auction!$C$5:$C$1000)-ROW(Auction!$C$5)+1),15)),"")} | H18: {=IFERROR(INDEX(Auction!$B$5:$B$1000,SMALL(IF(Auction!$C$5:$C$1000=$F$2,ROW(Auction!$C$5:$C$1000)-ROW(Auction!$C$5)+1),15)),"")} | J18: 15 | K18: {=IFERROR(INDEX(Auction!$A$5:$A$1000,SMALL(IF(Auction!$C$5:$C$1000=$J$2,ROW(Auction!$C$5:$C$1000)-ROW(Auction!$C$5)+1),15)),"")} | L18: {=IFERROR(INDEX(Auction!$B$5:$B$1000,SMALL(IF(Auction!$C$5:$C$1000=$J$2,ROW(Auction!$C$5:$C$1000)-ROW(Auction!$C$5)+1),15)),"")} | N18: 15 | O18: {=IFERROR(INDEX(Auction!$A$5:$A$1000,SMALL(IF(Auction!$C$5:$C$1000=$N$2,ROW(Auction!$C$5:$C$1000)-ROW(Auction!$C$5)+1),15)),"")} | P18: {=IFERROR(INDEX(Auction!$B$5:$B$1000,SMALL(IF(Auction!$C$5:$C$1000=$N$2,ROW(Auction!$C$5:$C$1000)-ROW(Auction!$C$5)+1),15)),"")} | R18: 15 | S18: {=IFERROR(INDEX(Auction!$A$5:$A$1000,SMALL(IF(Auction!$C$5:$C$1000=$R$2,ROW(Auction!$C$5:$C$1000)-ROW(Auction!$C$5)+1),15)),"")} | T18: {=IFERROR(INDEX(Auction!$B$5:$B$1000,SMALL(IF(Auction!$C$5:$C$1000=$R$2,ROW(Auction!$C$5:$C$1000)-ROW(Auction!$C$5)+1),15)),"")}
B19: Total Amount Spent | D19: =Balance!$C$4 | F19: Total Amount Spent | H19: =Balance!$C$5 | J19: Total Amount Spent | L19: =Balance!$C$6 | N19: Total Amount Spent | P19: =Balance!$C$7 | R19: Total Amount Spent | T19: =Balance!$C$8
B20: Total Amount Left | D20: =Balance!$D$4 | F20: Total Amount Left | H20: =Balance!$D$5 | J20: Total Amount Left | L20: =Balance!$D$6 | N20: Total Amount Left | P20: =Balance!$D$7 | R20: Total Amount Left | T20: =Balance!$D$8
B21: Total Amount | D21: =Balance!$B$4 | F21: Total Amount | H21: =Balance!$B$5 | J21: Total Amount | L21: =Balance!$B$6 | N21: Total Amount | P21: =Balance!$B$7 | R21: Total Amount | T21: =Balance!$B$8
B23: =Balance!$A$9 | F23: =Balance!$A$10 | J23: =Balance!$A$11 | N23: =Balance!$A$12 | R23: =Balance!$A$13
B24: S.No | C24: Player Name | D24: Amount | F24: S.No | G24: Player Name | H24: Amount | J24: S.No | K24: Player Name | L24: Amount | N24: S.No | O24: Player Name | P24: Amount | R24: S.No | S24: Player Name | T24: Amount
B25: 1 | C25: {=IFERROR(INDEX(Auction!$A$5:$A$1000,SMALL(IF(Auction!$C$5:$C$1000=$B$23,ROW(Auction!$C$5:$C$1000)-ROW(Auction!$C$5)+1),1)),"")} | D25: {=IFERROR(INDEX(Auction!$B$5:$B$1000,SMALL(IF(Auction!$C$5:$C$1000=$B$23,ROW(Auction!$C$5:$C$1000)-ROW(Auction!$C$5)+1),1)),"")} | F25: 1 | G25: {=IFERROR(INDEX(Auction!$A$5:$A$1000,SMALL(IF(Auction!$C$5:$C$1000=$F$23,ROW(Auction!$C$5:$C$1000)-ROW(Auction!$C$5)+1),1)),"")} | H25: {=IFERROR(INDEX(Auction!$B$5:$B$1000,SMALL(IF(Auction!$C$5:$C$1000=$F$23,ROW(Auction!$C$5:$C$1000)-ROW(Auction!$C$5)+1),1)),"")} | J25: 1 | K25: {=IFERROR(INDEX(Auction!$A$5:$A$1000,SMALL(IF(Auction!$C$5:$C$1000=$J$23,ROW(Auction!$C$5:$C$1000)-ROW(Auction!$C$5)+1),1)),"")} | L25: {=IFERROR(INDEX(Auction!$B$5:$B$1000,SMALL(IF(Auction!$C$5:$C$1000=$J$23,ROW(Auction!$C$5:$C$1000)-ROW(Auction!$C$5)+1),1)),"")} | N25: 1 | O25: {=IFERROR(INDEX(Auction!$A$5:$A$1000,SMALL(IF(Auction!$C$5:$C$1000=$N$23,ROW(Auction!$C$5:$C$1000)-ROW(Auction!$C$5)+1),1)),"")} | P25: {=IFERROR(INDEX(Auction!$B$5:$B$1000,SMALL(IF(Auction!$C$5:$C$1000=$N$23,ROW(Auction!$C$5:$C$1000)-ROW(Auction!$C$5)+1),1)),"")} | R25: 1 | S25: {=IFERROR(INDEX(Auction!$A$5:$A$1000,SMALL(IF(Auction!$C$5:$C$1000=$R$23,ROW(Auction!$C$5:$C$1000)-ROW(Auction!$C$5)+1),1)),"")} | T25: {=IFERROR(INDEX(Auction!$B$5:$B$1000,SMALL(IF(Auction!$C$5:$C$1000=$R$23,ROW(Auction!$C$5:$C$1000)-ROW(Auction!$C$5)+1),1)),"")}
B26: 2 | C26: {=IFERROR(INDEX(Auction!$A$5:$A$1000,SMALL(IF(Auction!$C$5:$C$1000=$B$23,ROW(Auction!$C$5:$C$1000)-ROW(Auction!$C$5)+1),2)),"")} | D26: {=IFERROR(INDEX(Auction!$B$5:$B$1000,SMALL(IF(Auction!$C$5:$C$1000=$B$23,ROW(Auction!$C$5:$C$1000)-ROW(Auction!$C$5)+1),2)),"")} | F26: 2 | G26: {=IFERROR(INDEX(Auction!$A$5:$A$1000,SMALL(IF(Auction!$C$5:$C$1000=$F$23,ROW(Auction!$C$5:$C$1000)-ROW(Auction!$C$5)+1),2)),"")} | H26: {=IFERROR(INDEX(Auction!$B$5:$B$1000,SMALL(IF(Auction!$C$5:$C$1000=$F$23,ROW(Auction!$C$5:$C$1000)-ROW(Auction!$C$5)+1),2)),"")} | J26: 2 | K26: {=IFERROR(INDEX(Auction!$A$5:$A$1000,SMALL(IF(Auction!$C$5:$C$1000=$J$23,ROW(Auction!$C$5:$C$1000)-ROW(Auction!$C$5)+1),2)),"")} | L26: {=IFERROR(INDEX(Auction!$B$5:$B$1000,SMALL(IF(Auction!$C$5:$C$1000=$J$23,ROW(Auction!$C$5:$C$1000)-ROW(Auction!$C$5)+1),2)),"")} | N26: 2 | O26: {=IFERROR(INDEX(Auction!$A$5:$A$1000,SMALL(IF(Auction!$C$5:$C$1000=$N$23,ROW(Auction!$C$5:$C$1000)-ROW(Auction!$C$5)+1),2)),"")} | P26: {=IFERROR(INDEX(Auction!$B$5:$B$1000,SMALL(IF(Auction!$C$5:$C$1000=$N$23,ROW(Auction!$C$5:$C$1000)-ROW(Auction!$C$5)+1),2)),"")} | R26: 2 | S26: {=IFERROR(INDEX(Auction!$A$5:$A$1000,SMALL(IF(Auction!$C$5:$C$1000=$R$23,ROW(Auction!$C$5:$C$1000)-ROW(Auction!$C$5)+1),2)),"")} | T26: {=IFERROR(INDEX(Auction!$B$5:$B$1000,SMALL(IF(Auction!$C$5:$C$1000=$R$23,ROW(Auction!$C$5:$C$1000)-ROW(Auction!$C$5)+1),2)),"")}
B27: 3 | C27: {=IFERROR(INDEX(Auction!$A$5:$A$1000,SMALL(IF(Auction!$C$5:$C$1000=$B$23,ROW(Auction!$C$5:$C$1000)-ROW(Auction!$C$5)+1),3)),"")} | D27: {=IFERROR(INDEX(Auction!$B$5:$B$1000,SMALL(IF(Auction!$C$5:$C$1000=$B$23,ROW(Auction!$C$5:$C$1000)-ROW(Auction!$C$5)+1),3)),"")} | F27: 3 | G27: {=IFERROR(INDEX(Auction!$A$5:$A$1000,SMALL(IF(Auction!$C$5:$C$1000=$F$23,ROW(Auction!$C$5:$C$1000)-ROW(Auction!$C$5)+1),3)),"")} | H27: {=IFERROR(INDEX(Auction!$B$5:$B$1000,SMALL(IF(Auction!$C$5:$C$1000=$F$23,ROW(Auction!$C$5:$C$1000)-ROW(Auction!$C$5)+1),3)),"")} | J27: 3 | K27: {=IFERROR(INDEX(Auction!$A$5:$A$1000,SMALL(IF(Auction!$C$5:$C$1000=$J$23,ROW(Auction!$C$5:$C$1000)-ROW(Auction!$C$5)+1),3)),"")} | L27: {=IFERROR(INDEX(Auction!$B$5:$B$1000,SMALL(IF(Auction!$C$5:$C$1000=$J$23,ROW(Auction!$C$5:$C$1000)-ROW(Auction!$C$5)+1),3)),"")} | N27: 3 | O27: {=IFERROR(INDEX(Auction!$A$5:$A$1000,SMALL(IF(Auction!$C$5:$C$1000=$N$23,ROW(Auction!$C$5:$C$1000)-ROW(Auction!$C$5)+1),3)),"")} | P27: {=IFERROR(INDEX(Auction!$B$5:$B$1000,SMALL(IF(Auction!$C$5:$C$1000=$N$23,ROW(Auction!$C$5:$C$1000)-ROW(Auction!$C$5)+1),3)),"")} | R27: 3 | S27: {=IFERROR(INDEX(Auction!$A$5:$A$1000,SMALL(IF(Auction!$C$5:$C$1000=$R$23,ROW(Auction!$C$5:$C$1000)-ROW(Auction!$C$5)+1),3)),"")} | T27: {=IFERROR(INDEX(Auction!$B$5:$B$1000,SMALL(IF(Auction!$C$5:$C$1000=$R$23,ROW(Auction!$C$5:$C$1000)-ROW(Auction!$C$5)+1),3)),"")}
B28: 4 | C28: {=IFERROR(INDEX(Auction!$A$5:$A$1000,SMALL(IF(Auction!$C$5:$C$1000=$B$23,ROW(Auction!$C$5:$C$1000)-ROW(Auction!$C$5)+1),4)),"")} | D28: {=IFERROR(INDEX(Auction!$B$5:$B$1000,SMALL(IF(Auction!$C$5:$C$1000=$B$23,ROW(Auction!$C$5:$C$1000)-ROW(Auction!$C$5)+1),4)),"")} | F28: 4 | G28: {=IFERROR(INDEX(Auction!$A$5:$A$1000,SMALL(IF(Auction!$C$5:$C$1000=$F$23,ROW(Auction!$C$5:$C$1000)-ROW(Auction!$C$5)+1),4)),"")} | H28: {=IFERROR(INDEX(Auction!$B$5:$B$1000,SMALL(IF(Auction!$C$5:$C$1000=$F$23,ROW(Auction!$C$5:$C$1000)-ROW(Auction!$C$5)+1),4)),"")} | J28: 4 | K28: {=IFERROR(INDEX(Auction!$A$5:$A$1000,SMALL(IF(Auction!$C$5:$C$1000=$J$23,ROW(Auction!$C$5:$C$1000)-ROW(Auction!$C$5)+1),4)),"")} | L28: {=IFERROR(INDEX(Auction!$B$5:$B$1000,SMALL(IF(Auction!$C$5:$C$1000=$J$23,ROW(Auction!$C$5:$C$1000)-ROW(Auction!$C$5)+1),4)),"")} | N28: 4 | O28: {=IFERROR(INDEX(Auction!$A$5:$A$1000,SMALL(IF(Auction!$C$5:$C$1000=$N$23,ROW(Auction!$C$5:$C$1000)-ROW(Auction!$C$5)+1),4)),"")} | P28: {=IFERROR(INDEX(Auction!$B$5:$B$1000,SMALL(IF(Auction!$C$5:$C$1000=$N$23,ROW(Auction!$C$5:$C$1000)-ROW(Auction!$C$5)+1),4)),"")} | R28: 4 | S28: {=IFERROR(INDEX(Auction!$A$5:$A$1000,SMALL(IF(Auction!$C$5:$C$1000=$R$23,ROW(Auction!$C$5:$C$1000)-ROW(Auction!$C$5)+1),4)),"")} | T28: {=IFERROR(INDEX(Auction!$B$5:$B$1000,SMALL(IF(Auction!$C$5:$C$1000=$R$23,ROW(Auction!$C$5:$C$1000)-ROW(Auction!$C$5)+1),4)),"")}
B29: 5 | C29: {=IFERROR(INDEX(Auction!$A$5:$A$1000,SMALL(IF(Auction!$C$5:$C$1000=$B$23,ROW(Auction!$C$5:$C$1000)-ROW(Auction!$C$5)+1),5)),"")} | D29: {=IFERROR(INDEX(Auction!$B$5:$B$1000,SMALL(IF(Auction!$C$5:$C$1000=$B$23,ROW(Auction!$C$5:$C$1000)-ROW(Auction!$C$5)+1),5)),"")} | F29: 5 | G29: {=IFERROR(INDEX(Auction!$A$5:$A$1000,SMALL(IF(Auction!$C$5:$C$1000=$F$23,ROW(Auction!$C$5:$C$1000)-ROW(Auction!$C$5)+1),5)),"")} | H29: {=IFERROR(INDEX(Auction!$B$5:$B$1000,SMALL(IF(Auction!$C$5:$C$1000=$F$23,ROW(Auction!$C$5:$C$1000)-ROW(Auction!$C$5)+1),5)),"")} | J29: 5 | K29: {=IFERROR(INDEX(Auction!$A$5:$A$1000,SMALL(IF(Auction!$C$5:$C$1000=$J$23,ROW(Auction!$C$5:$C$1000)-ROW(Auction!$C$5)+1),5)),"")} | L29: {=IFERROR(INDEX(Auction!$B$5:$B$1000,SMALL(IF(Auction!$C$5:$C$1000=$J$23,ROW(Auction!$C$5:$C$1000)-ROW(Auction!$C$5)+1),5)),"")} | N29: 5 | O29: {=IFERROR(INDEX(Auction!$A$5:$A$1000,SMALL(IF(Auction!$C$5:$C$1000=$N$23,ROW(Auction!$C$5:$C$1000)-ROW(Auction!$C$5)+1),5)),"")} | P29: {=IFERROR(INDEX(Auction!$B$5:$B$1000,SMALL(IF(Auction!$C$5:$C$1000=$N$23,ROW(Auction!$C$5:$C$1000)-ROW(Auction!$C$5)+1),5)),"")} | R29: 5 | S29: {=IFERROR(INDEX(Auction!$A$5:$A$1000,SMALL(IF(Auction!$C$5:$C$1000=$R$23,ROW(Auction!$C$5:$C$1000)-ROW(Auction!$C$5)+1),5)),"")} | T29: {=IFERROR(INDEX(Auction!$B$5:$B$1000,SMALL(IF(Auction!$C$5:$C$1000=$R$23,ROW(Auction!$C$5:$C$1000)-ROW(Auction!$C$5)+1),5)),"")}
B30: 6 | C30: {=IFERROR(INDEX(Auction!$A$5:$A$1000,SMALL(IF(Auction!$C$5:$C$1000=$B$23,ROW(Auction!$C$5:$C$1000)-ROW(Auction!$C$5)+1),6)),"")} | D30: {=IFERROR(INDEX(Auction!$B$5:$B$1000,SMALL(IF(Auction!$C$5:$C$1000=$B$23,ROW(Auction!$C$5:$C$1000)-ROW(Auction!$C$5)+1),6)),"")} | F30: 6 | G30: {=IFERROR(INDEX(Auction!$A$5:$A$1000,SMALL(IF(Auction!$C$5:$C$1000=$F$23,ROW(Auction!$C$5:$C$1000)-ROW(Auction!$C$5)+1),6)),"")} | H30: {=IFERROR(INDEX(Auction!$B$5:$B$1000,SMALL(IF(Auction!$C$5:$C$1000=$F$23,ROW(Auction!$C$5:$C$1000)-ROW(Auction!$C$5)+1),6)),"")} | J30: 6 | K30: {=IFERROR(INDEX(Auction!$A$5:$A$1000,SMALL(IF(Auction!$C$5:$C$1000=$J$23,ROW(Auction!$C$5:$C$1000)-ROW(Auction!$C$5)+1),6)),"")} | L30: {=IFERROR(INDEX(Auction!$B$5:$B$1000,SMALL(IF(Auction!$C$5:$C$1000=$J$23,ROW(Auction!$C$5:$C$1000)-ROW(Auction!$C$5)+1),6)),"")} | N30: 6 | O30: {=IFERROR(INDEX(Auction!$A$5:$A$1000,SMALL(IF(Auction!$C$5:$C$1000=$N$23,ROW(Auction!$C$5:$C$1000)-ROW(Auction!$C$5)+1),6)),"")} | P30: {=IFERROR(INDEX(Auction!$B$5:$B$1000,SMALL(IF(Auction!$C$5:$C$1000=$N$23,ROW(Auction!$C$5:$C$1000)-ROW(Auction!$C$5)+1),6)),"")} | R30: 6 | S30: {=IFERROR(INDEX(Auction!$A$5:$A$1000,SMALL(IF(Auction!$C$5:$C$1000=$R$23,ROW(Auction!$C$5:$C$1000)-ROW(Auction!$C$5)+1),6)),"")} | T30: {=IFERROR(INDEX(Auction!$B$5:$B$1000,SMALL(IF(Auction!$C$5:$C$1000=$R$23,ROW(Auction!$C$5:$C$1000)-ROW(Auction!$C$5)+1),6)),"")}
B31: 7 | C31: {=IFERROR(INDEX(Auction!$A$5:$A$1000,SMALL(IF(Auction!$C$5:$C$1000=$B$23,ROW(Auction!$C$5:$C$1000)-ROW(Auction!$C$5)+1),7)),"")} | D31: {=IFERROR(INDEX(Auction!$B$5:$B$1000,SMALL(IF(Auction!$C$5:$C$1000=$B$23,ROW(Auction!$C$5:$C$1000)-ROW(Auction!$C$5)+1),7)),"")} | F31: 7 | G31: {=IFERROR(INDEX(Auction!$A$5:$A$1000,SMALL(IF(Auction!$C$5:$C$1000=$F$23,ROW(Auction!$C$5:$C$1000)-ROW(Auction!$C$5)+1),7)),"")} | H31: {=IFERROR(INDEX(Auction!$B$5:$B$1000,SMALL(IF(Auction!$C$5:$C$1000=$F$23,ROW(Auction!$C$5:$C$1000)-ROW(Auction!$C$5)+1),7)),"")} | J31: 7 | K31: {=IFERROR(INDEX(Auction!$A$5:$A$1000,SMALL(IF(Auction!$C$5:$C$1000=$J$23,ROW(Auction!$C$5:$C$1000)-ROW(Auction!$C$5)+1),7)),"")} | L31: {=IFERROR(INDEX(Auction!$B$5:$B$1000,SMALL(IF(Auction!$C$5:$C$1000=$J$23,ROW(Auction!$C$5:$C$1000)-ROW(Auction!$C$5)+1),7)),"")} | N31: 7 | O31: {=IFERROR(INDEX(Auction!$A$5:$A$1000,SMALL(IF(Auction!$C$5:$C$1000=$N$23,ROW(Auction!$C$5:$C$1000)-ROW(Auction!$C$5)+1),7)),"")} | P31: {=IFERROR(INDEX(Auction!$B$5:$B$1000,SMALL(IF(Auction!$C$5:$C$1000=$N$23,ROW(Auction!$C$5:$C$1000)-ROW(Auction!$C$5)+1),7)),"")} | R31: 7 | S31: {=IFERROR(INDEX(Auction!$A$5:$A$1000,SMALL(IF(Auction!$C$5:$C$1000=$R$23,ROW(Auction!$C$5:$C$1000)-ROW(Auction!$C$5)+1),7)),"")} | T31: {=IFERROR(INDEX(Auction!$B$5:$B$1000,SMALL(IF(Auction!$C$5:$C$1000=$R$23,ROW(Auction!$C$5:$C$1000)-ROW(Auction!$C$5)+1),7)),"")}
B32: 8 | C32: {=IFERROR(INDEX(Auction!$A$5:$A$1000,SMALL(IF(Auction!$C$5:$C$1000=$B$23,ROW(Auction!$C$5:$C$1000)-ROW(Auction!$C$5)+1),8)),"")} | D32: {=IFERROR(INDEX(Auction!$B$5:$B$1000,SMALL(IF(Auction!$C$5:$C$1000=$B$23,ROW(Auction!$C$5:$C$1000)-ROW(Auction!$C$5)+1),8)),"")} | F32: 8 | G32: {=IFERROR(INDEX(Auction!$A$5:$A$1000,SMALL(IF(Auction!$C$5:$C$1000=$F$23,ROW(Auction!$C$5:$C$1000)-ROW(Auction!$C$5)+1),8)),"")} | H32: {=IFERROR(INDEX(Auction!$B$5:$B$1000,SMALL(IF(Auction!$C$5:$C$1000=$F$23,ROW(Auction!$C$5:$C$1000)-ROW(Auction!$C$5)+1),8)),"")} | J32: 8 | K32: {=IFERROR(INDEX(Auction!$A$5:$A$1000,SMALL(IF(Auction!$C$5:$C$1000=$J$23,ROW(Auction!$C$5:$C$1000)-ROW(Auction!$C$5)+1),8)),"")} | L32: {=IFERROR(INDEX(Auction!$B$5:$B$1000,SMALL(IF(Auction!$C$5:$C$1000=$J$23,ROW(Auction!$C$5:$C$1000)-ROW(Auction!$C$5)+1),8)),"")} | N32: 8 | O32: {=IFERROR(INDEX(Auction!$A$5:$A$1000,SMALL(IF(Auction!$C$5:$C$1000=$N$23,ROW(Auction!$C$5:$C$1000)-ROW(Auction!$C$5)+1),8)),"")} | P32: {=IFERROR(INDEX(Auction!$B$5:$B$1000,SMALL(IF(Auction!$C$5:$C$1000=$N$23,ROW(Auction!$C$5:$C$1000)-ROW(Auction!$C$5)+1),8)),"")} | R32: 8 | S32: {=IFERROR(INDEX(Auction!$A$5:$A$1000,SMALL(IF(Auction!$C$5:$C$1000=$R$23,ROW(Auction!$C$5:$C$1000)-ROW(Auction!$C$5)+1),8)),"")} | T32: {=IFERROR(INDEX(Auction!$B$5:$B$1000,SMALL(IF(Auction!$C$5:$C$1000=$R$23,ROW(Auction!$C$5:$C$1000)-ROW(Auction!$C$5)+1),8)),"")}
B33: 9 | C33: {=IFERROR(INDEX(Auction!$A$5:$A$1000,SMALL(IF(Auction!$C$5:$C$1000=$B$23,ROW(Auction!$C$5:$C$1000)-ROW(Auction!$C$5)+1),9)),"")} | D33: {=IFERROR(INDEX(Auction!$B$5:$B$1000,SMALL(IF(Auction!$C$5:$C$1000=$B$23,ROW(Auction!$C$5:$C$1000)-ROW(Auction!$C$5)+1),9)),"")} | F33: 9 | G33: {=IFERROR(INDEX(Auction!$A$5:$A$1000,SMALL(IF(Auction!$C$5:$C$1000=$F$23,ROW(Auction!$C$5:$C$1000)-ROW(Auction!$C$5)+1),9)),"")} | H33: {=IFERROR(INDEX(Auction!$B$5:$B$1000,SMALL(IF(Auction!$C$5:$C$1000=$F$23,ROW(Auction!$C$5:$C$1000)-ROW(Auction!$C$5)+1),9)),"")} | J33: 9 | K33: {=IFERROR(INDEX(Auction!$A$5:$A$1000,SMALL(IF(Auction!$C$5:$C$1000=$J$23,ROW(Auction!$C$5:$C$1000)-ROW(Auction!$C$5)+1),9)),"")} | L33: {=IFERROR(INDEX(Auction!$B$5:$B$1000,SMALL(IF(Auction!$C$5:$C$1000=$J$23,ROW(Auction!$C$5:$C$1000)-ROW(Auction!$C$5)+1),9)),"")} | N33: 9 | O33: {=IFERROR(INDEX(Auction!$A$5:$A$1000,SMALL(IF(Auction!$C$5:$C$1000=$N$23,ROW(Auction!$C$5:$C$1000)-ROW(Auction!$C$5)+1),9)),"")} | P33: {=IFERROR(INDEX(Auction!$B$5:$B$1000,SMALL(IF(Auction!$C$5:$C$1000=$N$23,ROW(Auction!$C$5:$C$1000)-ROW(Auction!$C$5)+1),9)),"")} | R33: 9 | S33: {=IFERROR(INDEX(Auction!$A$5:$A$1000,SMALL(IF(Auction!$C$5:$C$1000=$R$23,ROW(Auction!$C$5:$C$1000)-ROW(Auction!$C$5)+1),9)),"")} | T33: {=IFERROR(INDEX(Auction!$B$5:$B$1000,SMALL(IF(Auction!$C$5:$C$1000=$R$23,ROW(Auction!$C$5:$C$1000)-ROW(Auction!$C$5)+1),9)),"")}
B34: 10 | C34: {=IFERROR(INDEX(Auction!$A$5:$A$1000,SMALL(IF(Auction!$C$5:$C$1000=$B$23,ROW(Auction!$C$5:$C$1000)-ROW(Auction!$C$5)+1),10)),"")} | D34: {=IFERROR(INDEX(Auction!$B$5:$B$1000,SMALL(IF(Auction!$C$5:$C$1000=$B$23,ROW(Auction!$C$5:$C$1000)-ROW(Auction!$C$5)+1),10)),"")} | F34: 10 | G34: {=IFERROR(INDEX(Auction!$A$5:$A$1000,SMALL(IF(Auction!$C$5:$C$1000=$F$23,ROW(Auction!$C$5:$C$1000)-ROW(Auction!$C$5)+1),10)),"")} | H34: {=IFERROR(INDEX(Auction!$B$5:$B$1000,SMALL(IF(Auction!$C$5:$C$1000=$F$23,ROW(Auction!$C$5:$C$1000)-ROW(Auction!$C$5)+1),10)),"")} | J34: 10 | K34: {=IFERROR(INDEX(Auction!$A$5:$A$1000,SMALL(IF(Auction!$C$5:$C$1000=$J$23,ROW(Auction!$C$5:$C$1000)-ROW(Auction!$C$5)+1),10)),"")} | L34: {=IFERROR(INDEX(Auction!$B$5:$B$1000,SMALL(IF(Auction!$C$5:$C$1000=$J$23,ROW(Auction!$C$5:$C$1000)-ROW(Auction!$C$5)+1),10)),"")} | N34: 10 | O34: {=IFERROR(INDEX(Auction!$A$5:$A$1000,SMALL(IF(Auction!$C$5:$C$1000=$N$23,ROW(Auction!$C$5:$C$1000)-ROW(Auction!$C$5)+1),10)),"")} | P34: {=IFERROR(INDEX(Auction!$B$5:$B$1000,SMALL(IF(Auction!$C$5:$C$1000=$N$23,ROW(Auction!$C$5:$C$1000)-ROW(Auction!$C$5)+1),10)),"")} | R34: 10 | S34: {=IFERROR(INDEX(Auction!$A$5:$A$1000,SMALL(IF(Auction!$C$5:$C$1000=$R$23,ROW(Auction!$C$5:$C$1000)-ROW(Auction!$C$5)+1),10)),"")} | T34: {=IFERROR(INDEX(Auction!$B$5:$B$1000,SMALL(IF(Auction!$C$5:$C$1000=$R$23,ROW(Auction!$C$5:$C$1000)-ROW(Auction!$C$5)+1),10)),"")}
B35: 11 | C35: {=IFERROR(INDEX(Auction!$A$5:$A$1000,SMALL(IF(Auction!$C$5:$C$1000=$B$23,ROW(Auction!$C$5:$C$1000)-ROW(Auction!$C$5)+1),11)),"")} | D35: {=IFERROR(INDEX(Auction!$B$5:$B$1000,SMALL(IF(Auction!$C$5:$C$1000=$B$23,ROW(Auction!$C$5:$C$1000)-ROW(Auction!$C$5)+1),11)),"")} | F35: 11 | G35: {=IFERROR(INDEX(Auction!$A$5:$A$1000,SMALL(IF(Auction!$C$5:$C$1000=$F$23,ROW(Auction!$C$5:$C$1000)-ROW(Auction!$C$5)+1),11)),"")} | H35: {=IFERROR(INDEX(Auction!$B$5:$B$1000,SMALL(IF(Auction!$C$5:$C$1000=$F$23,ROW(Auction!$C$5:$C$1000)-ROW(Auction!$C$5)+1),11)),"")} | J35: 11 | K35: {=IFERROR(INDEX(Auction!$A$5:$A$1000,SMALL(IF(Auction!$C$5:$C$1000=$J$23,ROW(Auction!$C$5:$C$1000)-ROW(Auction!$C$5)+1),11)),"")} | L35: {=IFERROR(INDEX(Auction!$B$5:$B$1000,SMALL(IF(Auction!$C$5:$C$1000=$J$23,ROW(Auction!$C$5:$C$1000)-ROW(Auction!$C$5)+1),11)),"")} | N35: 11 | O35: {=IFERROR(INDEX(Auction!$A$5:$A$1000,SMALL(IF(Auction!$C$5:$C$1000=$N$23,ROW(Auction!$C$5:$C$1000)-ROW(Auction!$C$5)+1),11)),"")} | P35: {=IFERROR(INDEX(Auction!$B$5:$B$1000,SMALL(IF(Auction!$C$5:$C$1000=$N$23,ROW(Auction!$C$5:$C$1000)-ROW(Auction!$C$5)+1),11)),"")} | R35: 11 | S35: {=IFERROR(INDEX(Auction!$A$5:$A$1000,SMALL(IF(Auction!$C$5:$C$1000=$R$23,ROW(Auction!$C$5:$C$1000)-ROW(Auction!$C$5)+1),11)),"")} | T35: {=IFERROR(INDEX(Auction!$B$5:$B$1000,SMALL(IF(Auction!$C$5:$C$1000=$R$23,ROW(Auction!$C$5:$C$1000)-ROW(Auction!$C$5)+1),11)),"")}
B36: 12 | C36: {=IFERROR(INDEX(Auction!$A$5:$A$1000,SMALL(IF(Auction!$C$5:$C$1000=$B$23,ROW(Auction!$C$5:$C$1000)-ROW(Auction!$C$5)+1),12)),"")} | D36: {=IFERROR(INDEX(Auction!$B$5:$B$1000,SMALL(IF(Auction!$C$5:$C$1000=$B$23,ROW(Auction!$C$5:$C$1000)-ROW(Auction!$C$5)+1),12)),"")} | F36: 12 | G36: {=IFERROR(INDEX(Auction!$A$5:$A$1000,SMALL(IF(Auction!$C$5:$C$1000=$F$23,ROW(Auction!$C$5:$C$1000)-ROW(Auction!$C$5)+1),12)),"")} | H36: {=IFERROR(INDEX(Auction!$B$5:$B$1000,SMALL(IF(Auction!$C$5:$C$1000=$F$23,ROW(Auction!$C$5:$C$1000)-ROW(Auction!$C$5)+1),12)),"")} | J36: 12 | K36: {=IFERROR(INDEX(Auction!$A$5:$A$1000,SMALL(IF(Auction!$C$5:$C$1000=$J$23,ROW(Auction!$C$5:$C$1000)-ROW(Auction!$C$5)+1),12)),"")} | L36: {=IFERROR(INDEX(Auction!$B$5:$B$1000,SMALL(IF(Auction!$C$5:$C$1000=$J$23,ROW(Auction!$C$5:$C$1000)-ROW(Auction!$C$5)+1),12)),"")} | N36: 12 | O36: {=IFERROR(INDEX(Auction!$A$5:$A$1000,SMALL(IF(Auction!$C$5:$C$1000=$N$23,ROW(Auction!$C$5:$C$1000)-ROW(Auction!$C$5)+1),12)),"")} | P36: {=IFERROR(INDEX(Auction!$B$5:$B$1000,SMALL(IF(Auction!$C$5:$C$1000=$N$23,ROW(Auction!$C$5:$C$1000)-ROW(Auction!$C$5)+1),12)),"")} | R36: 12 | S36: {=IFERROR(INDEX(Auction!$A$5:$A$1000,SMALL(IF(Auction!$C$5:$C$1000=$R$23,ROW(Auction!$C$5:$C$1000)-ROW(Auction!$C$5)+1),12)),"")} | T36: {=IFERROR(INDEX(Auction!$B$5:$B$1000,SMALL(IF(Auction!$C$5:$C$1000=$R$23,ROW(Auction!$C$5:$C$1000)-ROW(Auction!$C$5)+1),12)),"")}
B37: 13 | C37: {=IFERROR(INDEX(Auction!$A$5:$A$1000,SMALL(IF(Auction!$C$5:$C$1000=$B$23,ROW(Auction!$C$5:$C$1000)-ROW(Auction!$C$5)+1),13)),"")} | D37: {=IFERROR(INDEX(Auction!$B$5:$B$1000,SMALL(IF(Auction!$C$5:$C$1000=$B$23,ROW(Auction!$C$5:$C$1000)-ROW(Auction!$C$5)+1),13)),"")} | F37: 13 | G37: {=IFERROR(INDEX(Auction!$A$5:$A$1000,SMALL(IF(Auction!$C$5:$C$1000=$F$23,ROW(Auction!$C$5:$C$1000)-ROW(Auction!$C$5)+1),13)),"")} | H37: {=IFERROR(INDEX(Auction!$B$5:$B$1000,SMALL(IF(Auction!$C$5:$C$1000=$F$23,ROW(Auction!$C$5:$C$1000)-ROW(Auction!$C$5)+1),13)),"")} | J37: 13 | K37: {=IFERROR(INDEX(Auction!$A$5:$A$1000,SMALL(IF(Auction!$C$5:$C$1000=$J$23,ROW(Auction!$C$5:$C$1000)-ROW(Auction!$C$5)+1),13)),"")} | L37: {=IFERROR(INDEX(Auction!$B$5:$B$1000,SMALL(IF(Auction!$C$5:$C$1000=$J$23,ROW(Auction!$C$5:$C$1000)-ROW(Auction!$C$5)+1),13)),"")} | N37: 13 | O37: {=IFERROR(INDEX(Auction!$A$5:$A$1000,SMALL(IF(Auction!$C$5:$C$1000=$N$23,ROW(Auction!$C$5:$C$1000)-ROW(Auction!$C$5)+1),13)),"")} | P37: {=IFERROR(INDEX(Auction!$B$5:$B$1000,SMALL(IF(Auction!$C$5:$C$1000=$N$23,ROW(Auction!$C$5:$C$1000)-ROW(Auction!$C$5)+1),13)),"")} | R37: 13 | S37: {=IFERROR(INDEX(Auction!$A$5:$A$1000,SMALL(IF(Auction!$C$5:$C$1000=$R$23,ROW(Auction!$C$5:$C$1000)-ROW(Auction!$C$5)+1),13)),"")} | T37: {=IFERROR(INDEX(Auction!$B$5:$B$1000,SMALL(IF(Auction!$C$5:$C$1000=$R$23,ROW(Auction!$C$5:$C$1000)-ROW(Auction!$C$5)+1),13)),"")}
B38: 14 | C38: {=IFERROR(INDEX(Auction!$A$5:$A$1000,SMALL(IF(Auction!$C$5:$C$1000=$B$23,ROW(Auction!$C$5:$C$1000)-ROW(Auction!$C$5)+1),14)),"")} | D38: {=IFERROR(INDEX(Auction!$B$5:$B$1000,SMALL(IF(Auction!$C$5:$C$1000=$B$23,ROW(Auction!$C$5:$C$1000)-ROW(Auction!$C$5)+1),14)),"")} | F38: 14 | G38: {=IFERROR(INDEX(Auction!$A$5:$A$1000,SMALL(IF(Auction!$C$5:$C$1000=$F$23,ROW(Auction!$C$5:$C$1000)-ROW(Auction!$C$5)+1),14)),"")} | H38: {=IFERROR(INDEX(Auction!$B$5:$B$1000,SMALL(IF(Auction!$C$5:$C$1000=$F$23,ROW(Auction!$C$5:$C$1000)-ROW(Auction!$C$5)+1),14)),"")} | J38: 14 | K38: {=IFERROR(INDEX(Auction!$A$5:$A$1000,SMALL(IF(Auction!$C$5:$C$1000=$J$23,ROW(Auction!$C$5:$C$1000)-ROW(Auction!$C$5)+1),14)),"")} | L38: {=IFERROR(INDEX(Auction!$B$5:$B$1000,SMALL(IF(Auction!$C$5:$C$1000=$J$23,ROW(Auction!$C$5:$C$1000)-ROW(Auction!$C$5)+1),14)),"")} | N38: 14 | O38: {=IFERROR(INDEX(Auction!$A$5:$A$1000,SMALL(IF(Auction!$C$5:$C$1000=$N$23,ROW(Auction!$C$5:$C$1000)-ROW(Auction!$C$5)+1),14)),"")} | P38: {=IFERROR(INDEX(Auction!$B$5:$B$1000,SMALL(IF(Auction!$C$5:$C$1000=$N$23,ROW(Auction!$C$5:$C$1000)-ROW(Auction!$C$5)+1),14)),"")} | R38: 14 | S38: {=IFERROR(INDEX(Auction!$A$5:$A$1000,SMALL(IF(Auction!$C$5:$C$1000=$R$23,ROW(Auction!$C$5:$C$1000)-ROW(Auction!$C$5)+1),14)),"")} | T38: {=IFERROR(INDEX(Auction!$B$5:$B$1000,SMALL(IF(Auction!$C$5:$C$1000=$R$23,ROW(Auction!$C$5:$C$1000)-ROW(Auction!$C$5)+1),14)),"")}
B39: 15 | C39: {=IFERROR(INDEX(Auction!$A$5:$A$1000,SMALL(IF(Auction!$C$5:$C$1000=$B$23,ROW(Auction!$C$5:$C$1000)-ROW(Auction!$C$5)+1),15)),"")} | D39: {=IFERROR(INDEX(Auction!$B$5:$B$1000,SMALL(IF(Auction!$C$5:$C$1000=$B$23,ROW(Auction!$C$5:$C$1000)-ROW(Auction!$C$5)+1),15)),"")} | F39: 15 | G39: {=IFERROR(INDEX(Auction!$A$5:$A$1000,SMALL(IF(Auction!$C$5:$C$1000=$F$23,ROW(Auction!$C$5:$C$1000)-ROW(Auction!$C$5)+1),15)),"")} | H39: {=IFERROR(INDEX(Auction!$B$5:$B$1000,SMALL(IF(Auction!$C$5:$C$1000=$F$23,ROW(Auction!$C$5:$C$1000)-ROW(Auction!$C$5)+1),15)),"")} | J39: 15 | K39: {=IFERROR(INDEX(Auction!$A$5:$A$1000,SMALL(IF(Auction!$C$5:$C$1000=$J$23,ROW(Auction!$C$5:$C$1000)-ROW(Auction!$C$5)+1),15)),"")} | L39: {=IFERROR(INDEX(Auction!$B$5:$B$1000,SMALL(IF(Auction!$C$5:$C$1000=$J$23,ROW(Auction!$C$5:$C$1000)-ROW(Auction!$C$5)+1),15)),"")} | N39: 15 | O39: {=IFERROR(INDEX(Auction!$A$5:$A$1000,SMALL(IF(Auction!$C$5:$C$1000=$N$23,ROW(Auction!$C$5:$C$1000)-ROW(Auction!$C$5)+1),15)),"")} | P39: {=IFERROR(INDEX(Auction!$B$5:$B$1000,SMALL(IF(Auction!$C$5:$C$1000=$N$23,ROW(Auction!$C$5:$C$1000)-ROW(Auction!$C$5)+1),15)),"")} | R39: 15 | S39: {=IFERROR(INDEX(Auction!$A$5:$A$1000,SMALL(IF(Auction!$C$5:$C$1000=$R$23,ROW(Auction!$C$5:$C$1000)-ROW(Auction!$C$5)+1),15)),"")} | T39: {=IFERROR(INDEX(Auction!$B$5:$B$1000,SMALL(IF(Auction!$C$5:$C$1000=$R$23,ROW(Auction!$C$5:$C$1000)-ROW(Auction!$C$5)+1),15)),"")}
B40: Total Amount Spent | D40: =Balance!$C$9 | F40: Total Amount Spent | H40: =Balance!$C$10 | J40: Total Amount Spent | L40: =Balance!$C$11 | N40: Total Amount Spent | P40: =Balance!$C$12 | R40: Total Amount Spent | T40: =Balance!$C$13
B41: Total Amount Left | D41: =Balance!$D$9 | F41: Total Amount Left | H41: =Balance!$D$10 | J41: Total Amount Left | L41: =Balance!$D$11 | N41: Total Amount Left | P41: =Balance!$D$12 | R41: Total Amount Left | T41: =Balance!$D$13
B42: Total Amount | D42: =Balance!$B$9 | F42: Total Amount | H42: =Balance!$B$10 | J42: Total Amount | L42: =Balance!$B$11 | N42: Total Amount | P42: =Balance!$B$12 | R42: Total Amount | T42: =Balance!$B$13
...

Sheet Mumbai Indians
A1: =Balance!A4
A3: Purse (Cr) | B3: =Balance!B4
A4: Spent (Cr) | B4: =Balance!C4
A5: Balance (Cr) | B5: =Balance!D4
A6: Players | B6: =Balance!E4
A8: Player | B8: Price (Cr) | C8: Role | D8: Hand | E8: Country | F8: City
A9: {=IFERROR(INDEX(Auction!$A$5:$A$1000,SMALL(IF(Auction!$C$5:$C$1000=$A$1,ROW(Auction!$C$5:$C$1000)-ROW(Auction!$C$5)+1),ROWS($A$9:A9))),"")} | B9: {=IFERROR(INDEX(Auction!$B$5:$B$1000,SMALL(IF(Auction!$C$5:$C$1000=$A$1,ROW(Auction!$C$5:$C$1000)-ROW(Auction!$C$5)+1),ROWS($A$9:A9))),"")} | C9: =IFERROR(T(VLOOKUP($A9,Players!$A:$E,2,FALSE)),"") | D9: =IFERROR(T(VLOOKUP($A9,Players!$A:$E,3,FALSE)),"") | E9: =IFERROR(T(VLOOKUP($A9,Players!$A:$E,4,FALSE)),"") | F9: =IFERROR(T(VLOOKUP($A9,Players!$A:$E,5,FALSE)),"")
A10: {=IFERROR(INDEX(Auction!$A$5:$A$1000,SMALL(IF(Auction!$C$5:$C$1000=$A$1,ROW(Auction!$C$5:$C$1000)-ROW(Auction!$C$5)+1),ROWS($A$9:A10))),"")} | B10: {=IFERROR(INDEX(Auction!$B$5:$B$1000,SMALL(IF(Auction!$C$5:$C$1000=$A$1,ROW(Auction!$C$5:$C$1000)-ROW(Auction!$C$5)+1),ROWS($A$9:A10))),"")} | C10: =IFERROR(T(VLOOKUP($A10,Players!$A:$E,2,FALSE)),"") | D10: =IFERROR(T(VLOOKUP($A10,Players!$A:$E,3,FALSE)),"") | E10: =IFERROR(T(VLOOKUP($A10,Players!$A:$E,4,FALSE)),"") | F10: =IFERROR(T(VLOOKUP($A10,Players!$A:$E,5,FALSE)),"")
A11: {=IFERROR(INDEX(Auction!$A$5:$A$1000,SMALL(IF(Auction!$C$5:$C$1000=$A$1,ROW(Auction!$C$5:$C$1000)-ROW(Auction!$C$5)+1),ROWS($A$9:A11))),"")} | B11: {=IFERROR(INDEX(Auction!$B$5:$B$1000,SMALL(IF(Auction!$C$5:$C$1000=$A$1,ROW(Auction!$C$5:$C$1000)-ROW(Auction!$C$5)+1),ROWS($A$9:A11))),"")} | C11: =IFERROR(T(VLOOKUP($A11,Players!$A:$E,2,FALSE)),"") | D11: =IFERROR(T(VLOOKUP($A11,Players!$A:$E,3,FALSE)),"") | E11: =IFERROR(T(VLOOKUP($A11,Players!$A:$E,4,FALSE)),"") | F11: =IFERROR(T(VLOOKUP($A11,Players!$A:$E,5,FALSE)),"")
A12: {=IFERROR(INDEX(Auction!$A$5:$A$1000,SMALL(IF(Auction!$C$5:$C$1000=$A$1,ROW(Auction!$C$5:$C$1000)-ROW(Auction!$C$5)+1),ROWS($A$9:A12))),"")} | B12: {=IFERROR(INDEX(Auction!$B$5:$B$1000,SMALL(IF(Auction!$C$5:$C$1000=$A$1,ROW(Auction!$C$5:$C$1000)-ROW(Auction!$C$5)+1),ROWS($A$9:A12))),"")} | C12: =IFERROR(T(VLOOKUP($A12,Players!$A:$E,2,FALSE)),"") | D12: =IFERROR(T(VLOOKUP($A12,Players!$A:$E,3,FALSE)),"") | E12: =IFERROR(T(VLOOKUP($A12,Players!$A:$E,4,FALSE)),"") | F12: =IFERROR(T(VLOOKUP($A12,Players!$A:$E,5,FALSE)),"")
A13: {=IFERROR(INDEX(Auction!$A$5:$A$1000,SMALL(IF(Auction!$C$5:$C$1000=$A$1,ROW(Auction!$C$5:$C$1000)-ROW(Auction!$C$5)+1),ROWS($A$9:A13))),"")} | B13: {=IFERROR(INDEX(Auction!$B$5:$B$1000,SMALL(IF(Auction!$C$5:$C$1000=$A$1,ROW(Auction!$C$5:$C$1000)-ROW(Auction!$C$5)+1),ROWS($A$9:A13))),"")} | C13: =IFERROR(T(VLOOKUP($A13,Players!$A:$E,2,FALSE)),"") | D13: =IFERROR(T(VLOOKUP($A13,Players!$A:$E,3,FALSE)),"") | E13: =IFERROR(T(VLOOKUP($A13,Players!$A:$E,4,FALSE)),"") | F13: =IFERROR(T(VLOOKUP($A13,Players!$A:$E,5,FALSE)),"")
A14: {=IFERROR(INDEX(Auction!$A$5:$A$1000,SMALL(IF(Auction!$C$5:$C$1000=$A$1,ROW(Auction!$C$5:$C$1000)-ROW(Auction!$C$5)+1),ROWS($A$9:A14))),"")} | B14: {=IFERROR(INDEX(Auction!$B$5:$B$1000,SMALL(IF(Auction!$C$5:$C$1000=$A$1,ROW(Auction!$C$5:$C$1000)-ROW(Auction!$C$5)+1),ROWS($A$9:A14))),"")} | C14: =IFERROR(T(VLOOKUP($A14,Players!$A:$E,2,FALSE)),"") | D14: =IFERROR(T(VLOOKUP($A14,Players!$A:$E,3,FALSE)),"") | E14: =IFERROR(T(VLOOKUP($A14,Players!$A:$E,4,FALSE)),"") | F14: =IFERROR(T(VLOOKUP($A14,Players!$A:$E,5,FALSE)),"")
A15: {=IFERROR(INDEX(Auction!$A$5:$A$1000,SMALL(IF(Auction!$C$5:$C$1000=$A$1,ROW(Auction!$C$5:$C$1000)-ROW(Auction!$C$5)+1),ROWS($A$9:A15))),"")} | B15: {=IFERROR(INDEX(Auction!$B$5:$B$1000,SMALL(IF(Auction!$C$5:$C$1000=$A$1,ROW(Auction!$C$5:$C$1000)-ROW(Auction!$C$5)+1),ROWS($A$9:A15))),"")} | C15: =IFERROR(T(VLOOKUP($A15,Players!$A:$E,2,FALSE)),"") | D15: =IFERROR(T(VLOOKUP($A15,Players!$A:$E,3,FALSE)),"") | E15: =IFERROR(T(VLOOKUP($A15,Players!$A:$E,4,FALSE)),"") | F15: =IFERROR(T(VLOOKUP($A15,Players!$A:$E,5,FALSE)),"")
A16: {=IFERROR(INDEX(Auction!$A$5:$A$1000,SMALL(IF(Auction!$C$5:$C$1000=$A$1,ROW(Auction!$C$5:$C$1000)-ROW(Auction!$C$5)+1),ROWS($A$9:A16))),"")} | B16: {=IFERROR(INDEX(Auction!$B$5:$B$1000,SMALL(IF(Auction!$C$5:$C$1000=$A$1,ROW(Auction!$C$5:$C$1000)-ROW(Auction!$C$5)+1),ROWS($A$9:A16))),"")} | C16: =IFERROR(T(VLOOKUP($A16,Players!$A:$E,2,FALSE)),"") | D16: =IFERROR(T(VLOOKUP($A16,Players!$A:$E,3,FALSE)),"") | E16: =IFERROR(T(VLOOKUP($A16,Players!$A:$E,4,FALSE)),"") | F16: =IFERROR(T(VLOOKUP($A16,Players!$A:$E,5,FALSE)),"")
A17: {=IFERROR(INDEX(Auction!$A$5:$A$1000,SMALL(IF(Auction!$C$5:$C$1000=$A$1,ROW(Auction!$C$5:$C$1000)-ROW(Auction!$C$5)+1),ROWS($A$9:A17))),"")} | B17: {=IFERROR(INDEX(Auction!$B$5:$B$1000,SMALL(IF(Auction!$C$5:$C$1000=$A$1,ROW(Auction!$C$5:$C$1000)-ROW(Auction!$C$5)+1),ROWS($A$9:A17))),"")} | C17: =IFERROR(T(VLOOKUP($A17,Players!$A:$E,2,FALSE)),"") | D17: =IFERROR(T(VLOOKUP($A17,Players!$A:$E,3,FALSE)),"") | E17: =IFERROR(T(VLOOKUP($A17,Players!$A:$E,4,FALSE)),"") | F17: =IFERROR(T(VLOOKUP($A17,Players!$A:$E,5,FALSE)),"")
A18: {=IFERROR(INDEX(Auction!$A$5:$A$1000,SMALL(IF(Auction!$C$5:$C$1000=$A$1,ROW(Auction!$C$5:$C$1000)-ROW(Auction!$C$5)+1),ROWS($A$9:A18))),"")} | B18: {=IFERROR(INDEX(Auction!$B$5:$B$1000,SMALL(IF(Auction!$C$5:$C$1000=$A$1,ROW(Auction!$C$5:$C$1000)-ROW(Auction!$C$5)+1),ROWS($A$9:A18))),"")} | C18: =IFERROR(T(VLOOKUP($A18,Players!$A:$E,2,FALSE)),"") | D18: =IFERROR(T(VLOOKUP($A18,Players!$A:$E,3,FALSE)),"") | E18: =IFERROR(T(VLOOKUP($A18,Players!$A:$E,4,FALSE)),"") | F18: =IFERROR(T(VLOOKUP($A18,Players!$A:$E,5,FALSE)),"")
A19: {=IFERROR(INDEX(Auction!$A$5:$A$1000,SMALL(IF(Auction!$C$5:$C$1000=$A$1,ROW(Auction!$C$5:$C$1000)-ROW(Auction!$C$5)+1),ROWS($A$9:A19))),"")} | B19: {=IFERROR(INDEX(Auction!$B$5:$B$1000,SMALL(IF(Auction!$C$5:$C$1000=$A$1,ROW(Auction!$C$5:$C$1000)-ROW(Auction!$C$5)+1),ROWS($A$9:A19))),"")} | C19: =IFERROR(T(VLOOKUP($A19,Players!$A:$E,2,FALSE)),"") | D19: =IFERROR(T(VLOOKUP($A19,Players!$A:$E,3,FALSE)),"") | E19: =IFERROR(T(VLOOKUP($A19,Players!$A:$E,4,FALSE)),"") | F19: =IFERROR(T(VLOOKUP($A19,Players!$A:$E,5,FALSE)),"")
A20: {=IFERROR(INDEX(Auction!$A$5:$A$1000,SMALL(IF(Auction!$C$5:$C$1000=$A$1,ROW(Auction!$C$5:$C$1000)-ROW(Auction!$C$5)+1),ROWS($A$9:A20))),"")} | B20: {=IFERROR(INDEX(Auction!$B$5:$B$1000,SMALL(IF(Auction!$C$5:$C$1000=$A$1,ROW(Auction!$C$5:$C$1000)-ROW(Auction!$C$5)+1),ROWS($A$9:A20))),"")} | C20: =IFERROR(T(VLOOKUP($A20,Players!$A:$E,2,FALSE)),"") | D20: =IFERROR(T(VLOOKUP($A20,Players!$A:$E,3,FALSE)),"") | E20: =IFERROR(T(VLOOKUP($A20,Players!$A:$E,4,FALSE)),"") | F20: =IFERROR(T(VLOOKUP($A20,Players!$A:$E,5,FALSE)),"")
... A48: {=IFERROR(INDEX(Auction!$A$5:$A$1000,SMALL(IF(Auction!$C$5:$C$1000=$A$1,ROW(Auction!$C$5:$C$1000)-ROW(Auction!$C$5)+1),ROWS($A$9:A48))),"")} | B48: {=IFERROR(INDEX(Auction!$B$5:$B$1000,SMALL(IF(Auction!$C$5:$C$1000=$A$1,ROW(Auction!$C$5:$C$1000)-ROW(Auction!$C$5)+1),ROWS($A$9:A48))),"")} | C48: =IFERROR(T(VLOOKUP($A48,Players!$A:$E,2,FALSE)),"") | D48: =IFERROR(T(VLOOKUP($A48,Players!$A:$E,3,FALSE)),"") | E48: =IFERROR(T(VLOOKUP($A48,Players!$A:$E,4,FALSE)),"") | F48: =IFERROR(T(VLOOKUP($A48,Players!$A:$E,5,FALSE)),"")

Sheet Royal Challangers Banglore
A1: =Balance!A5
A3: Purse (Cr) | B3: =Balance!B5
A4: Spent (Cr) | B4: =Balance!C5
A5: Balance (Cr) | B5: =Balance!D5
A6: Players | B6: =Balance!E5
A8: Player | B8: Price (Cr) | C8: Role | D8: Hand | E8: Country | F8: City
A9: {=IFERROR(INDEX(Auction!$A$5:$A$1000,SMALL(IF(Auction!$C$5:$C$1000=$A$1,ROW(Auction!$C$5:$C$1000)-ROW(Auction!$C$5)+1),ROWS($A$9:A9))),"")} | B9: {=IFERROR(INDEX(Auction!$B$5:$B$1000,SMALL(IF(Auction!$C$5:$C$1000=$A$1,ROW(Auction!$C$5:$C$1000)-ROW(Auction!$C$5)+1),ROWS($A$9:A9))),"")} | C9: =IFERROR(T(VLOOKUP($A9,Players!$A:$E,2,FALSE)),"") | D9: =IFERROR(T(VLOOKUP($A9,Players!$A:$E,3,FALSE)),"") | E9: =IFERROR(T(VLOOKUP($A9,Players!$A:$E,4,FALSE)),"") | F9: =IFERROR(T(VLOOKUP($A9,Players!$A:$E,5,FALSE)),"")
A10: {=IFERROR(INDEX(Auction!$A$5:$A$1000,SMALL(IF(Auction!$C$5:$C$1000=$A$1,ROW(Auction!$C$5:$C$1000)-ROW(Auction!$C$5)+1),ROWS($A$9:A10))),"")} | B10: {=IFERROR(INDEX(Auction!$B$5:$B$1000,SMALL(IF(Auction!$C$5:$C$1000=$A$1,ROW(Auction!$C$5:$C$1000)-ROW(Auction!$C$5)+1),ROWS($A$9:A10))),"")} | C10: =IFERROR(T(VLOOKUP($A10,Players!$A:$E,2,FALSE)),"") | D10: =IFERROR(T(VLOOKUP($A10,Players!$A:$E,3,FALSE)),"") | E10: =IFERROR(T(VLOOKUP($A10,Players!$A:$E,4,FALSE)),"") | F10: =IFERROR(T(VLOOKUP($A10,Players!$A:$E,5,FALSE)),"")
A11: {=IFERROR(INDEX(Auction!$A$5:$A$1000,SMALL(IF(Auction!$C$5:$C$1000=$A$1,ROW(Auction!$C$5:$C$1000)-ROW(Auction!$C$5)+1),ROWS($A$9:A11))),"")} | B11: {=IFERROR(INDEX(Auction!$B$5:$B$1000,SMALL(IF(Auction!$C$5:$C$1000=$A$1,ROW(Auction!$C$5:$C$1000)-ROW(Auction!$C$5)+1),ROWS($A$9:A11))),"")} | C11: =IFERROR(T(VLOOKUP($A11,Players!$A:$E,2,FALSE)),"") | D11: =IFERROR(T(VLOOKUP($A11,Players!$A:$E,3,FALSE)),"") | E11: =IFERROR(T(VLOOKUP($A11,Players!$A:$E,4,FALSE)),"") | F11: =IFERROR(T(VLOOKUP($A11,Players!$A:$E,5,FALSE)),"")
